Workbook

Sheet Schedule March_26
B1: No. | C1: GROUP | D1: NAME | E1: POSITION | F1: 46057 | G1: 46058 | H1: 46059 | I1: 46060 | J1: 46061 | K1: 46062 | L1: 46063 | M1: 46064 | N1: 46065 | O1: 46066 | P1: 46067 | Q1: 46068 | R1: 46069 | S1: 46070 | T1: 46071 | U1: 46072 | V1: 46073 | W1: 46074 | X1: 46075 | Y1: 46076 | Z1: 46077 | AA1: 46078 | AB1: 46079 | AC1: 46080 | AD1: 46081 | AE1: 46082 | AF1: 46083 | AG1: 46084 | AH1: 46085 | AI1: 46086 | AJ1: 46087 | AK1: 46088 | AL1: 46089 | AM1: 46090 | AN1: 46091 | AO1: 46092 | AP1: 46093 | AQ1: 46094 | AR1: 46095 | AS1: 46096 | AT1: 46097 | AU1: 46098 | AV1: 46099 | AW1: 46100 | AX1: 46101 | AY1: 46102 | AZ1: 46103 | BA1: 46104 | BB1: 46105 | BC1: 46106 | BD1: 46107 | BE1: 46108 | BF1: 46109 | BG1: 46110 | BH1: 46111 | BI1: 46112 | BJ1: 46113 | BK1: 46114 | BL1: 46115 | BN1: Workdays | BO1: Day off | BP1: A | BQ1: B | BR1: C | BS1: D | BT1: E
B2: No. | C2: New | F2: =CHOOSE(WEEKDAY(F1),"Sun","Mon","Tue","Wed","Thu","Fri","Sat") -> Wed | G2: =CHOOSE(WEEKDAY(G1),"Sun","Mon","Tue","Wed","Thu","Fri","Sat") -> Thu | H2: =CHOOSE(WEEKDAY(H1),"Sun","Mon","Tue","Wed","Thu","Fri","Sat") -> Fri | I2: =CHOOSE(WEEKDAY(I1),"Sun","Mon","Tue","Wed","Thu","Fri","Sat") -> Sat | J2: =CHOOSE(WEEKDAY(J1),"Sun","Mon","Tue","Wed","Thu","Fri","Sat") -> Sun | K2: =CHOOSE(WEEKDAY(K1),"Sun","Mon","Tue","Wed","Thu","Fri","Sat") -> Mon | L2: =CHOOSE(WEEKDAY(L1),"Sun","Mon","Tue","Wed","Thu","Fri","Sat") -> Tue | M2: =CHOOSE(WEEKDAY(M1),"Sun","Mon","Tue","Wed","Thu","Fri","Sat") -> Wed | ... BL2: =CHOOSE(WEEKDAY(BL1),"Sun","Mon","Tue","Wed","Thu","Fri","Sat") -> Fri
F3: =COUNTIF(F4:F125,"<>0") -> 118 | G3: =COUNTIF(G4:G125,"<>0") -> 118 | H3: =COUNTIF(H4:H125,"<>0") -> 118 | I3: =COUNTIF(I4:I125,"<>0") -> 67 | J3: =COUNTIF(J4:J125,"<>0") -> 64 | K3: =COUNTIF(K4:K125,"<>0") -> 103 | L3: =COUNTIF(L4:L125,"<>0") -> 116 | M3: =COUNTIF(M4:M125,"<>0") -> 112 | ... BL3: =COUNTIF(BL4:BL125,"<>0") -> 115
A4: 1 | B4: 1 | C4: T1 | D4: Nguyễn Quốc Duy | E4: Agent | F4: A | G4: A | H4: A | I4: A | J4: 0 | K4: E | L4: E | M4: E | N4: E | Q4: 0 | R4: H | S4: H | T4: H | U4: H | V4: H | W4: 0 | X4: E | Y4: E | Z4: E | AA4: E | AB4: E | AC4: E | AD4: 0 | AE4: D | AF4: D | AG4: D | AH4: D | AI4: D | AJ4: D | AK4: D | AL4: 0 | AM4: D | AN4: D | AO4: D | AP4: D | AQ4: D | AR4: D | AS4: D | AT4: 0 | AU4: C | AV4: C | AW4: C | AX4: C | AY4: 0 | AZ4: C | BA4: C | BB4: C | BC4: C | BD4: C | BE4: C | BF4: C | BG4: 0 | BH4: B | BI4: B | BJ4: B | BK4: B | BL4: B | BN4: =SUM(BP4:BT4) -> 44 | BO4: =COUNTIF($F4:$BM4,"0") -> 8 | BP4: =COUNTIF($F4:$BM4,BP$1) -> 4 | BQ4: =COUNTIF($F4:$BM4,BQ$1) -> 5 | BR4: =COUNTIF($F4:$BM4,BR$1) -> 11 | BS4: =COUNTIF($F4:$BM4,BS$1) -> 14 | BT4: =COUNTIF($F4:$BM4,BT$1) -> 10
A5: 2 | B5: 2 | C5: T1 | D5: Trương Thị Như Ngọc | E5: Agent | F5: A | G5: A | H5: A | I5: A | J5: 0 | K5: E | L5: E | M5: E | N5: E | O5: E | Q5: 0 | R5: H | S5: H | T5: H | U5: H | V5: H | W5: 0 | X5: E | Y5: E | Z5: E | AA5: E | AB5: E | AC5: E | AD5: 0 | AE5: D | AF5: D | AG5: D | AH5: D | AI5: D | AJ5: D | AK5: D | AL5: 0 | AM5: D | AN5: D | AO5: D | AP5: D | AQ5: D | AR5: D | AS5: D | AT5: 0 | AU5: C | AV5: C | AW5: C | AX5: C | AY5: 0 | AZ5: C | BA5: C | BB5: C | BC5: C | BD5: C | BE5: C | BF5: C | BG5: 0 | BH5: B | BI5: B | BJ5: B | BK5: B | BL5: B | BN5: =SUM(BP5:BT5) -> 45 | BO5: =COUNTIF($F5:$BM5,"0") -> 8 | BP5: =COUNTIF($F5:$BM5,BP$1) -> 4 | BQ5: =COUNTIF($F5:$BM5,BQ$1) -> 5 | BR5: =COUNTIF($F5:$BM5,BR$1) -> 11 | BS5: =COUNTIF($F5:$BM5,BS$1) -> 14 | BT5: =COUNTIF($F5:$BM5,BT$1) -> 11
A6: 3 | B6: 3 | C6: T1 | D6: Nguyễn Thành Quang | E6: Agent | F6: A | G6: A | H6: A | I6: A | J6: 0 | K6: E | L6: E | M6: E | N6: E | O6: E | P6: E | Q6: 0 | R6: H | S6: H | T6: H | U6: H | V6: H | W6: 0 | X6: E | Y6: E | Z6: E | AA6: E | AB6: E | AC6: E | AD6: E | AE6: 0 | AF6: D | AG6: D | AH6: D | AI6: D | AJ6: D | AK6: D | AL6: D | AM6: 0 | AN6: D | AO6: D | AP6: D | AQ6: D | AR6: D | AS6: D | AT6: 0 | AU6: C | AV6: C | AW6: C | AX6: C | AY6: 0 | AZ6: C | BA6: C | BB6: C | BC6: C | BD6: C | BE6: C | BF6: C | BG6: 0 | BH6: B | BI6: B | BJ6: B | BK6: B | BL6: B | BN6: =SUM(BP6:BT6) -> 46 | BO6: =COUNTIF($F6:$BM6,"0") -> 8 | BP6: =COUNTIF($F6:$BM6,BP$1) -> 4 | BQ6: =COUNTIF($F6:$BM6,BQ$1) -> 5 | BR6: =COUNTIF($F6:$BM6,BR$1) -> 11 | BS6: =COUNTIF($F6:$BM6,BS$1) -> 13 | BT6: =COUNTIF($F6:$BM6,BT$1) -> 13
A7: 4 | B7: 4 | C7: T1 | D7: Phan Hoàng Chin Na | E7: Agent | F7: A | G7: A | H7: A | I7: A | J7: 0 | K7: E | L7: E | M7: E | N7: E | O7: E | P7: E | Q7: 0 | R7: E | S7: H | T7: E | U7: E | V7: E | W7: E | X7: 0 | Y7: E | Z7: E | AA7: E | AB7: E | AC7: E | AD7: E | AE7: 0 | AF7: D | AG7: D | AH7: D | AI7: D | AJ7: D | AK7: D | AL7: 0 | AM7: D | AN7: D | AO7: D | AP7: D | AQ7: D | AR7: D | AS7: D | AT7: 0 | AU7: C | AV7: C | AW7: C | AX7: C | AY7: 0 | AZ7: C | BA7: C | BB7: C | BC7: C | BD7: C | BE7: C | BF7: C | BG7: 0 | BH7: B | BI7: B | BJ7: B | BK7: B | BL7: B | BN7: =SUM(BP7:BT7) -> 50 | BO7: =COUNTIF($F7:$BM7,"0") -> 8 | BP7: =COUNTIF($F7:$BM7,BP$1) -> 4 | BQ7: =COUNTIF($F7:$BM7,BQ$1) -> 5 | BR7: =COUNTIF($F7:$BM7,BR$1) -> 11 | BS7: =COUNTIF($F7:$BM7,BS$1) -> 13 | BT7: =COUNTIF($F7:$BM7,BT$1) -> 17
A8: 5 | B8: 5 | C8: T1 | D8: Lưu Ngọc Mai | E8: Agent | F8: A | G8: A | H8: A | I8: A | J8: 0 | K8: E | L8: E | M8: E | N8: E | O8: E | P8: 0 | Q8: D | R8: D | S8: D | T8: D | U8: D | V8: D | W8: 0 | X8: D | Y8: D | Z8: D | AA8: D | AB8: D | AC8: D | AD8: D | AE8: 0 | AF8: D | AG8: D | AH8: D | AI8: D | AJ8: D | AK8: D | AL8: 0 | AM8: D | AN8: D | AO8: D | AP8: D | AQ8: D | AR8: D | AS8: D | AT8: 0 | AU8: C | AV8: C | AW8: C | AX8: C | AY8: 0 | AZ8: C | BA8: C | BB8: C | BC8: C | BD8: C | BE8: C | BF8: C | BG8: 0 | BH8: B | BI8: B | BJ8: B | BK8: B | BL8: B | BN8: =SUM(BP8:BT8) -> 51 | BO8: =COUNTIF($F8:$BM8,"0") -> 8 | BP8: =COUNTIF($F8:$BM8,BP$1) -> 4 | BQ8: =COUNTIF($F8:$BM8,BQ$1) -> 5 | BR8: =COUNTIF($F8:$BM8,BR$1) -> 11 | BS8: =COUNTIF($F8:$BM8,BS$1) -> 26 | BT8: =COUNTIF($F8:$BM8,BT$1) -> 5
A9: 6 | B9: 6 | C9: T2 | D9: Ngô Thục Oanh | E9: Agent | F9: E | G9: E | H9: E | I9: 0 | J9: E | K9: E | L9: E | M9: E | N9: E | Q9: 0 | R9: H | S9: H | T9: E | U9: E | V9: E | W9: 0 | X9: D | Y9: D | Z9: D | AA9: D | AB9: D | AC9: D | AD9: D | AE9: 0 | AF9: D | AG9: D | AH9: D | AI9: D | AJ9: D | AK9: D | AL9: D | AM9: 0 | AN9: C | AO9: C | AP9: C | AQ9: C | AR9: 0 | AS9: C | AT9: C | AU9: C | AV9: C | AW9: C | AX9: C | AY9: C | AZ9: 0 | BA9: B | BB9: B | BC9: B | BD9: B | BE9: B | BF9: B | BG9: 0 | BH9: E | BI9: E | BJ9: E | BK9: E | BL9: E | BN9: =SUM(BP9:BT9) -> 47 | BO9: =COUNTIF($F9:$BM9,"0") -> 8 | BP9: =COUNTIF($F9:$BM9,BP$1) -> 0 | BQ9: =COUNTIF($F9:$BM9,BQ$1) -> 6 | BR9: =COUNTIF($F9:$BM9,BR$1) -> 11 | BS9: =COUNTIF($F9:$BM9,BS$1) -> 14 | BT9: =COUNTIF($F9:$BM9,BT$1) -> 16
A10: 7 | B10: 7 | C10: T2 | D10: Lê Khương Duy | E10: Agent | F10: E | G10: E | H10: E | I10: 0 | J10: E | K10: E | L10: E | M10: E | N10: E | O10: E | P10: 0 | Q10: E | R10: E | S10: E | T10: H | U10: H | V10: E | W10: 0 | X10: D | Y10: D | Z10: D | AA10: D | AB10: D | AC10: D | AD10: D | AE10: 0 | AF10: D | AG10: D | AH10: D | AI10: D | AJ10: D | AK10: D | AL10: D | AM10: 0 | AN10: C | AO10: C | AP10: C | AQ10: C | AR10: 0 | AS10: C | AT10: C | AU10: C | AV10: C | AW10: C | AX10: C | AY10: C | AZ10: 0 | BA10: B | BB10: B | BC10: B | BD10: B | BE10: B | BF10: 0 | BG10: B | BH10: B | BI10: B | BJ10: B | BK10: B | BL10: B | BN10: =SUM(BP10:BT10) -> 49 | BO10: =COUNTIF($F10:$BM10,"0") -> 8 | BP10: =COUNTIF($F10:$BM10,BP$1) -> 0 | BQ10: =COUNTIF($F10:$BM10,BQ$1) -> 11 | BR10: =COUNTIF($F10:$BM10,BR$1) -> 11 | BS10: =COUNTIF($F10:$BM10,BS$1) -> 14 | BT10: =COUNTIF($F10:$BM10,BT$1) -> 13
A11: 8 | B11: 8 | C11: T2 | D11: Trần Hà Phương Uyên | E11: Agent | F11: E | G11: E | H11: E | I11: 0 | J11: E | K11: E | L11: E | M11: E | N11: E | O11: E | P11: 0 | Q11: D | R11: D | S11: D | T11: D | U11: D | V11: D | W11: 0 | X11: D | Y11: D | Z11: D | AA11: D | AB11: D | AC11: D | AD11: D | AE11: 0 | AF11: D | AG11: D | AH11: D | AI11: D | AJ11: D | AK11: D | AL11: D | AM11: 0 | AN11: C | AO11: C | AP11: C | AQ11: C | AR11: 0 | AS11: C | AT11: C | AU11: C | AV11: C | AW11: C | AX11: C | AY11: C | AZ11: 0 | BA11: B | BB11: B | BC11: B | BD11: B | BE11: B | BF11: 0 | BG11: B | BH11: B | BI11: B | BJ11: B | BK11: B | BL11: B | BN11: =SUM(BP11:BT11) -> 51 | BO11: =COUNTIF($F11:$BM11,"0") -> 8 | BP11: =COUNTIF($F11:$BM11,BP$1) -> 0 | BQ11: =COUNTIF($F11:$BM11,BQ$1) -> 11 | BR11: =COUNTIF($F11:$BM11,BR$1) -> 11 | BS11: =COUNTIF($F11:$BM11,BS$1) -> 20 | BT11: =COUNTIF($F11:$BM11,BT$1) -> 9
A12: 9 | B12: 9 | C12: T2 | D12: Vũ Đình Nguyễn | E12: Agent | F12: E | G12: E | H12: E | I12: 0 | J12: E | K12: E | L12: E | M12: E | N12: E | O12: E | Q12: 0 | R12: H | S12: H | T12: H | U12: H | V12: H | W12: 0 | X12: D | Y12: D | Z12: D | AA12: D | AB12: D | AC12: D | AD12: D | AE12: 0 | AF12: D | AG12: D | AH12: D | AI12: D | AJ12: D | AK12: D | AL12: D | AM12: 0 | AN12: C | AO12: C | AP12: C | AQ12: C | AR12: 0 | AS12: C | AT12: C | AU12: C | AV12: C | AW12: C | AX12: C | AY12: C | AZ12: 0 | BA12: B | BB12: B | BC12: B | BD12: B | BE12: B | BF12: 0 | BG12: B | BH12: B | BI12: B | BJ12: B | BK12: B | BL12: B | BN12: =SUM(BP12:BT12) -> 45 | BO12: =COUNTIF($F12:$BM12,"0") -> 8 | BP12: =COUNTIF($F12:$BM12,BP$1) -> 0 | BQ12: =COUNTIF($F12:$BM12,BQ$1) -> 11 | BR12: =COUNTIF($F12:$BM12,BR$1) -> 11 | BS12: =COUNTIF($F12:$BM12,BS$1) -> 14 | BT12: =COUNTIF($F12:$BM12,BT$1) -> 9
A13: 10 | B13: 10 | C13: T2 | D13: Ngô Minh Đức | E13: Agent | F13: E | G13: E | H13: E | I13: 0 | J13: E | K13: E | L13: E | M13: E | N13: E | O13: E | P13: 0 | Q13: E | R13: E | S13: H | T13: H | U13: H | V13: H | W13: 0 | X13: D | Y13: D | Z13: D | AA13: D | AB13: D | AC13: D | AD13: D | AE13: 0 | AF13: D | AG13: D | AH13: D | AI13: D | AJ13: D | AK13: D | AL13: D | AM13: 0 | AN13: C | AO13: C | AP13: C | AQ13: C | AR13: 0 | AS13: C | AT13: C | AU13: C | AV13: C | AW13: C | AX13: C | AY13: C | AZ13: 0 | BA13: B | BB13: B | BC13: B | BD13: B | BE13: B | BF13: 0 | BG13: B | BH13: B | BI13: B | BJ13: B | BK13: B | BL13: B | BN13: =SUM(BP13:BT13) -> 47 | BO13: =COUNTIF($F13:$BM13,"0") -> 8 | BP13: =COUNTIF($F13:$BM13,BP$1) -> 0 | BQ13: =COUNTIF($F13:$BM13,BQ$1) -> 11 | BR13: =COUNTIF($F13:$BM13,BR$1) -> 11 | BS13: =COUNTIF($F13:$BM13,BS$1) -> 14 | BT13: =COUNTIF($F13:$BM13,BT$1) -> 11
A14: 11 | B14: 11 | C14: T3 | D14: Trần Đình Tú | E14: Agent | F14: E | G14: E | H14: E | I14: E | J14: 0 | K14: E | L14: E | M14: E | N14: E | O14: E | P14: E | Q14: 0 | R14: D | S14: D | T14: D | U14: D | V14: D | W14: D | X14: 0 | Y14: D | Z14: D | AA14: D | AB14: D | AC14: D | AD14: D | AE14: D | AF14: 0 | AG14: C | AH14: C | AI14: C | AJ14: C | AK14: 0 | AL14: C | AM14: C | AN14: C | AO14: C | AP14: C | AQ14: C | AR14: C | AS14: 0 | AT14: B | AU14: B | AV14: B | AW14: B | AX14: B | AY14: 0 | AZ14: B | BA14: B | BB14: B | BC14: B | BD14: B | BE14: B | BF14: B | BG14: 0 | BH14: A | BI14: A | BJ14: A | BK14: A | BL14: A | BN14: =SUM(BP14:BT14) -> 51 | BO14: =COUNTIF($F14:$BM14,"0") -> 8 | BP14: =COUNTIF($F14:$BM14,BP$1) -> 5 | BQ14: =COUNTIF($F14:$BM14,BQ$1) -> 12 | BR14: =COUNTIF($F14:$BM14,BR$1) -> 11 | BS14: =COUNTIF($F14:$BM14,BS$1) -> 13 | BT14: =COUNTIF($F14:$BM14,BT$1) -> 10
A15: 12 | B15: 12 | C15: T3 | D15: Huỳnh Thị Thanh Huyền | E15: Agent | F15: E | G15: E | H15: E | I15: E | J15: 0 | K15: E | L15: E | M15: E | N15: E | O15: E | P15: 0 | R15: H | S15: H | T15: H | U15: H | V15: D | W15: D | X15: 0 | Y15: D | Z15: D | AA15: D | AB15: D | AC15: D | AD15: D | AE15: D | AF15: 0 | AG15: C | AH15: C | AI15: C | AJ15: C | AK15: C | AL15: 0 | AM15: C | AN15: C | AO15: C | AP15: C | AQ15: C | AR15: C | AS15: 0 | AT15: B | AU15: B | AV15: B | AW15: B | AX15: B | AY15: 0 | AZ15: B | BA15: B | BB15: B | BC15: B | BD15: B | BE15: B | BF15: B | BG15: 0 | BH15: A | BI15: A | BJ15: A | BK15: A | BL15: A | BN15: =SUM(BP15:BT15) -> 46 | BO15: =COUNTIF($F15:$BM15,"0") -> 8 | BP15: =COUNTIF($F15:$BM15,BP$1) -> 5 | BQ15: =COUNTIF($F15:$BM15,BQ$1) -> 12 | BR15: =COUNTIF($F15:$BM15,BR$1) -> 11 | BS15: =COUNTIF($F15:$BM15,BS$1) -> 9 | BT15: =COUNTIF($F15:$BM15,BT$1) -> 9
A16: 13 | B16: 13 | C16: T3 | D16: Đỗ Lê Quốc Thành | E16: Agent | F16: E | G16: E | H16: E | I16: E | J16: 0 | K16: E | L16: E | M16: E | Q16: 0 | R16: H | S16: H | T16: H | U16: D | V16: D | W16: D | X16: 0 | Y16: D | Z16: D | AA16: D | AB16: D | AC16: D | AD16: D | AE16: D | AF16: 0 | AG16: C | AH16: C | AI16: C | AJ16: C | AK16: 0 | AL16: C | AM16: C | AN16: C | AO16: C | AP16: C | AQ16: C | AR16: C | AS16: 0 | AT16: B | AU16: B | AV16: B | AW16: B | AX16: B | AY16: 0 | AZ16: B | BA16: B | BB16: B | BC16: B | BD16: B | BE16: B | BF16: B | BG16: 0 | BH16: A | BI16: A | BJ16: A | BK16: A | BL16: A | BN16: =SUM(BP16:BT16) -> 45 | BO16: =COUNTIF($F16:$BM16,"0") -> 8 | BP16: =COUNTIF($F16:$BM16,BP$1) -> 5 | BQ16: =COUNTIF($F16:$BM16,BQ$1) -> 12 | BR16: =COUNTIF($F16:$BM16,BR$1) -> 11 | BS16: =COUNTIF($F16:$BM16,BS$1) -> 10 | BT16: =COUNTIF($F16:$BM16,BT$1) -> 7
A17: 14 | B17: 14 | C17: T3 | D17: Nguyễn Khánh Duy | E17: Agent | F17: E | G17: E | H17: E | I17: E | J17: 0 | K17: E | L17: E | M17: E | N17: E | O17: E | P17: 0 | Q17: D | R17: D | S17: D | T17: D | U17: D | V17: D | W17: D | X17: 0 | Y17: D | Z17: D | AA17: D | AB17: D | AC17: D | AD17: D | AE17: D | AF17: 0 | AG17: C | AH17: C | AI17: C | AJ17: C | AK17: 0 | AL17: C | AM17: C | AN17: C | AO17: C | AP17: C | AQ17: C | AR17: C | AS17: 0 | AT17: B | AU17: B | AV17: B | AW17: B | AX17: B | AY17: B | AZ17: 0 | BA17: B | BB17: B | BC17: B | BD17: B | BE17: B | BF17: B | BG17: 0 | BH17: A | BI17: A | BJ17: A | BK17: A | BL17: A | BN17: =SUM(BP17:BT17) -> 51 | BO17: =COUNTIF($F17:$BM17,"0") -> 8 | BP17: =COUNTIF($F17:$BM17,BP$1) -> 5 | BQ17: =COUNTIF($F17:$BM17,BQ$1) -> 12 | BR17: =COUNTIF($F17:$BM17,BR$1) -> 11 | BS17: =COUNTIF($F17:$BM17,BS$1) -> 14 | BT17: =COUNTIF($F17:$BM17,BT$1) -> 9
A18: 15 | B18: 15 | C18: T3 | D18: Nguyễn Mai Việt Tính | E18: Agent | F18: E | G18: E | H18: E | I18: E | J18: 0 | K18: E | L18: E | M18: E | N18: E | O18: E | P18: 0 | R18: H | S18: H | T18: H | U18: H | V18: H | X18: 0 | Y18: D | Z18: D | AA18: D | AB18: D | AC18: D | AD18: D | AE18: D | AF18: 0 | AG18: C | AH18: C | AI18: C | AJ18: C | AK18: 0 | AL18: C | AM18: C | AN18: C | AO18: C | AP18: C | AQ18: C | AR18: C | AS18: 0 | AT18: B | AU18: B | AV18: B | AW18: B | AX18: B | AY18: 0 | AZ18: B | BA18: B | BB18: B | BC18: B | BD18: B | BE18: B | BF18: B | BG18: 0 | BH18: A | BI18: A | BJ18: A | BK18: A | BL18: A | BN18: =SUM(BP18:BT18) -> 44 | BO18: =COUNTIF($F18:$BM18,"0") -> 8 | BP18: =COUNTIF($F18:$BM18,BP$1) -> 5 | BQ18: =COUNTIF($F18:$BM18,BQ$1) -> 12 | BR18: =COUNTIF($F18:$BM18,BR$1) -> 11 | BS18: =COUNTIF($F18:$BM18,BS$1) -> 7 | BT18: =COUNTIF($F18:$BM18,BT$1) -> 9
A19: 16 | B19: 16 | C19: T4 | D19: Võ Tuấn Vĩ | E19: Agent | F19: E | G19: E | H19: E | I19: 0 | J19: D | K19: D | L19: D | M19: D | N19: D | Q19: 0 | R19: H | S19: H | T19: H | U19: H | V19: H | W19: 0 | X19: C | Y19: C | Z19: C | AA19: C | AB19: C | AC19: C | AD19: 0 | AE19: C | AF19: C | AG19: C | AH19: C | AI19: C | AJ19: C | AK19: 0 | AL19: B | AM19: B | AN19: B | AO19: B | AP19: B | AQ19: B | AR19: 0 | AS19: B | AT19: B | AU19: B | AV19: B | AW19: B | AX19: B | AY19: B | AZ19: 0 | BA19: A | BB19: A | BC19: A | BD19: A | BE19: A | BF19: 0 | BG19: A | BH19: A | BI19: A | BJ19: A | BK19: A | BL19: A | BN19: =SUM(BP19:BT19) -> 44 | BO19: =COUNTIF($F19:$BM19,"0") -> 8 | BP19: =COUNTIF($F19:$BM19,BP$1) -> 11 | BQ19: =COUNTIF($F19:$BM19,BQ$1) -> 13 | BR19: =COUNTIF($F19:$BM19,BR$1) -> 12 | BS19: =COUNTIF($F19:$BM19,BS$1) -> 5 | BT19: =COUNTIF($F19:$BM19,BT$1) -> 3
A20: 17 | B20: 17 | C20: T4 | D20: Nguyễn Hữu Thọ | E20: Agent | F20: E | G20: E | H20: E | I20: 0 | J20: D | K20: D | L20: D | M20: D | N20: D | O20: D | P20: D | Q20: 0 | R20: D | S20: D | T20: D | U20: D | V20: D | Y20: 0 | Z20: C | AA20: C | AB20: C | AC20: C | AD20: C | AE20: 0 | AF20: C | AG20: C | AH20: C | AI20: C | AJ20: C | AK20: 0 | AL20: B | AM20: B | AN20: B | AO20: B | AP20: B | AQ20: B | AR20: 0 | AS20: B | AT20: B | AU20: B | AV20: B | AW20: B | AX20: B | AY20: 0 | AZ20: A | BA20: A | BB20: A | BC20: A | BD20: A | BE20: A | BF20: 0 | BG20: A | BH20: A | BI20: A | BJ20: A | BK20: A | BL20: A | BN20: =SUM(BP20:BT20) -> 49 | BO20: =COUNTIF($F20:$BM20,"0") -> 8 | BP20: =COUNTIF($F20:$BM20,BP$1) -> 12 | BQ20: =COUNTIF($F20:$BM20,BQ$1) -> 12 | BR20: =COUNTIF($F20:$BM20,BR$1) -> 10 | BS20: =COUNTIF($F20:$BM20,BS$1) -> 12 | BT20: =COUNTIF($F20:$BM20,BT$1) -> 3
A21: 18 | B21: 18 | C21: T4 | D21: Nhâm Bổn Tường | E21: Agent | F21: E | G21: E | H21: E | I21: 0 | J21: D | K21: D | L21: D | M21: D | N21: D | O21: D | P21: D | Q21: 0 | R21: H | S21: H | T21: H | U21: H | V21: H | X21: 0 | Y21: C | Z21: C | AA21: C | AB21: C | AC21: C | AD21: 0 | AE21: C | AF21: C | AG21: C | AH21: C | AI21: C | AJ21: C | AK21: C | AL21: 0 | AM21: B | AN21: B | AO21: B | AP21: B | AQ21: B | AR21: 0 | AS21: B | AT21: B | AU21: B | AV21: B | AW21: B | AX21: B | AY21: B | AZ21: 0 | BA21: A | BB21: A | BC21: A | BD21: A | BE21: A | BF21: 0 | BG21: A | BH21: A | BI21: A | BJ21: A | BK21: A | BL21: A | BN21: =SUM(BP21:BT21) -> 45 | BO21: =COUNTIF($F21:$BM21,"0") -> 8 | BP21: =COUNTIF($F21:$BM21,BP$1) -> 11 | BQ21: =COUNTIF($F21:$BM21,BQ$1) -> 12 | BR21: =COUNTIF($F21:$BM21,BR$1) -> 12 | BS21: =COUNTIF($F21:$BM21,BS$1) -> 7 | BT21: =COUNTIF($F21:$BM21,BT$1) -> 3
A22: 19 | B22: 20 | C22: T4 | D22: Nguyễn Phương Nam | E22: Agent | F22: E | G22: E | H22: E | I22: 0 | J22: D | K22: D | L22: D | M22: D | N22: D | O22: D | P22: D | Q22: 0 | R22: D | S22: D | T22: D | U22: D | V22: D | W22: D | X22: D | Y22: 0 | Z22: C | AA22: C | AB22: C | AC22: C | AD22: 0 | AE22: C | AF22: C | AG22: C | AH22: C | AI22: C | AJ22: C | AK22: C | AL22: 0 | AM22: B | AN22: B | AO22: B | AP22: B | AQ22: B | AR22: 0 | AS22: B | AT22: B | AU22: B | AV22: B | AW22: B | AX22: B | AY22: B | AZ22: 0 | BA22: A | BB22: A | BC22: A | BD22: A | BE22: A | BF22: 0 | BG22: A | BH22: A | BI22: A | BJ22: A | BK22: A | BL22: A | BN22: =SUM(BP22:BT22) -> 51 | BO22: =COUNTIF($F22:$BM22,"0") -> 8 | BP22: =COUNTIF($F22:$BM22,BP$1) -> 11 | BQ22: =COUNTIF($F22:$BM22,BQ$1) -> 12 | BR22: =COUNTIF($F22:$BM22,BR$1) -> 11 | BS22: =COUNTIF($F22:$BM22,BS$1) -> 14 | BT22: =COUNTIF($F22:$BM22,BT$1) -> 3
A23: 20 | B23: 22 | C23: T5 | D23: Nguyễn Đặng Ngọc Giàu | E23: Agent | F23: D | G23: D | H23: D | I23: D | J23: 0 | K23: D | L23: D | M23: D | N23: D | O23: D | P23: D | Q23: D | R23: 0 | S23: C | T23: C | U23: C | V23: C | W23: 0 | X23: C | Y23: C | Z23: C | AA23: C | AB23: C | AC23: C | AD23: C | AE23: 0 | AF23: B | AG23: B | AH23: B | AI23: B | AJ23: B | AK23: 0 | AL23: B | AM23: B | AN23: B | AO23: B | AP23: B | AQ23: B | AR23: B | AS23: 0 | AT23: A | AU23: A | AV23: A | AW23: A | AX23: A | AY23: 0 | AZ23: A | BA23: A | BB23: A | BC23: A | BD23: A | BE23: A | BF23: A | BG23: 0 | BH23: A | BI23: A | BJ23: A | BK23: A | BL23: A | BN23: =SUM(BP23:BT23) -> 51 | BO23: =COUNTIF($F23:$BM23,"0") -> 8 | BP23: =COUNTIF($F23:$BM23,BP$1) -> 17 | BQ23: =COUNTIF($F23:$BM23,BQ$1) -> 12 | BR23: =COUNTIF($F23:$BM23,BR$1) -> 11 | BS23: =COUNTIF($F23:$BM23,BS$1) -> 11 | BT23: =COUNTIF($F23:$BM23,BT$1) -> 0
A24: 21 | B24: 23 | C24: T5 | D24: Phạm Sỹ Thái | E24: Agent | F24: D | G24: D | H24: D | I24: D | J24: 0 | K24: D | L24: D | M24: D | N24: D | O24: D | P24: D | Q24: D | R24: 0 | S24: C | T24: C | U24: C | V24: C | W24: 0 | X24: C | Y24: C | Z24: C | AA24: C | AB24: C | AC24: C | AD24: C | AE24: 0 | AF24: B | AG24: B | AH24: B | AI24: B | AJ24: B | AK24: 0 | AL24: B | AM24: B | AN24: B | AO24: B | AP24: B | AQ24: B | AR24: B | AS24: 0 | AT24: A | AU24: A | AV24: A | AW24: A | AX24: A | AY24: 0 | AZ24: A | BA24: A | BB24: A | BC24: A | BD24: A | BE24: A | BF24: A | BG24: 0 | BH24: A | BI24: A | BJ24: A | BK24: A | BL24: A | BN24: =SUM(BP24:BT24) -> 51 | BO24: =COUNTIF($F24:$BM24,"0") -> 8 | BP24: =COUNTIF($F24:$BM24,BP$1) -> 17 | BQ24: =COUNTIF($F24:$BM24,BQ$1) -> 12 | BR24: =COUNTIF($F24:$BM24,BR$1) -> 11 | BS24: =COUNTIF($F24:$BM24,BS$1) -> 11 | BT24: =COUNTIF($F24:$BM24,BT$1) -> 0
A25: 22 | B25: 24 | C25: T5 | D25: Trương Tấn Thành Trung Hiếu | E25: Agent | F25: D | G25: D | H25: D | I25: D | J25: 0 | K25: D | L25: D | M25: D | N25: D | O25: D | P25: D | Q25: D | R25: 0 | S25: C | T25: C | U25: C | V25: C | W25: 0 | X25: C | Y25: C | Z25: C | AA25: C | AB25: C | AC25: C | AD25: C | AE25: 0 | AF25: B | AG25: B | AH25: B | AI25: B | AJ25: B | AK25: 0 | AL25: B | AM25: B | AN25: B | AO25: B | AP25: B | AQ25: B | AR25: B | AS25: 0 | AT25: A | AU25: A | AV25: A | AW25: A | AX25: A | AY25: 0 | AZ25: A | BA25: A | BB25: A | BC25: A | BD25: A | BE25: A | BF25: A | BG25: 0 | BH25: A | BI25: A | BJ25: A | BK25: A | BL25: A | BN25: =SUM(BP25:BT25) -> 51 | BO25: =COUNTIF($F25:$BM25,"0") -> 8 | BP25: =COUNTIF($F25:$BM25,BP$1) -> 17 | BQ25: =COUNTIF($F25:$BM25,BQ$1) -> 12 | BR25: =COUNTIF($F25:$BM25,BR$1) -> 11 | BS25: =COUNTIF($F25:$BM25,BS$1) -> 11 | BT25: =COUNTIF($F25:$BM25,BT$1) -> 0
A26: 23 | B26: 25 | C26: T5 | D26: Lê Huỳnh Minh Anh | E26: Agent | F26: D | G26: D | H26: D | I26: D | J26: 0 | K26: D | L26: D | M26: D | N26: D | O26: D | Q26: 0 | R26: H | S26: H | T26: H | U26: H | V26: H | W26: 0 | X26: C | Y26: C | Z26: C | AA26: C | AB26: C | AC26: C | AD26: C | AE26: 0 | AF26: B | AG26: B | AH26: B | AI26: B | AJ26: B | AK26: B | AL26: 0 | AM26: B | AN26: B | AO26: B | AP26: B | AQ26: B | AR26: B | AS26: 0 | AT26: A | AU26: A | AV26: A | AW26: A | AX26: A | AY26: 0 | AZ26: A | BA26: A | BB26: A | BC26: A | BD26: A | BE26: A | BF26: A | BG26: 0 | BH26: A | BI26: A | BJ26: A | BK26: A | BL26: A | BN26: =SUM(BP26:BT26) -> 45 | BO26: =COUNTIF($F26:$BM26,"0") -> 8 | BP26: =COUNTIF($F26:$BM26,BP$1) -> 17 | BQ26: =COUNTIF($F26:$BM26,BQ$1) -> 12 | BR26: =COUNTIF($F26:$BM26,BR$1) -> 7 | BS26: =COUNTIF($F26:$BM26,BS$1) -> 9 | BT26: =COUNTIF($F26:$BM26,BT$1) -> 0
A27: 24 | B27: 27 | C27: T6 | D27: Hồ Trọng Thiện | E27: Agent | F27: D | G27: D | H27: D | I27: D | J27: D | K27: 0 | L27: C | M27: C | N27: C | O27: C | P27: 0 | Q27: C | R27: C | S27: C | T27: C | U27: C | V27: C | W27: C | X27: 0 | Y27: B | Z27: B | AA27: B | AB27: B | AC27: B | AD27: 0 | AE27: B | AF27: B | AG27: B | AH27: B | AI27: B | AJ27: B | AK27: B | AL27: 0 | AM27: A | AN27: A | AO27: A | AP27: A | AQ27: A | AR27: 0 | AS27: A | AT27: A | AU27: A | AV27: A | AW27: A | AX27: A | AY27: A | AZ27: 0 | BA27: A | BB27: A | BC27: A | BD27: A | BE27: A | BF27: 0 | BG27: E | BH27: E | BI27: E | BJ27: E | BK27: E | BL27: E | BN27: =SUM(BP27:BT27) -> 51 | BO27: =COUNTIF($F27:$BM27,"0") -> 8 | BP27: =COUNTIF($F27:$BM27,BP$1) -> 17 | BQ27: =COUNTIF($F27:$BM27,BQ$1) -> 12 | BR27: =COUNTIF($F27:$BM27,BR$1) -> 11 | BS27: =COUNTIF($F27:$BM27,BS$1) -> 5 | BT27: =COUNTIF($F27:$BM27,BT$1) -> 6
A28: 25 | B28: 28 | C28: T6 | D28: Lê Công Triết | E28: Agent | F28: D | G28: D | H28: D | I28: D | J28: D | K28: 0 | L28: C | M28: C | N28: C | O28: C | P28: C | Q28: 0 | R28: H | S28: H | T28: H | U28: H | V28: H | W28: 0 | X28: B | Y28: B | Z28: B | AA28: B | AB28: B | AC28: B | AD28: 0 | AE28: B | AF28: B | AG28: B | AH28: B | AI28: B | AJ28: B | AK28: B | AL28: 0 | AM28: A | AN28: A | AO28: A | AP28: A | AQ28: A | AR28: 0 | AS28: A | AT28: A | AU28: A | AV28: A | AW28: A | AX28: A | AY28: A | AZ28: 0 | BA28: A | BB28: A | BC28: A | BD28: A | BE28: A | BF28: 0 | BG28: E | BH28: E | BI28: E | BJ28: E | BK28: E | BL28: E | BN28: =SUM(BP28:BT28) -> 46 | BO28: =COUNTIF($F28:$BM28,"0") -> 8 | BP28: =COUNTIF($F28:$BM28,BP$1) -> 17 | BQ28: =COUNTIF($F28:$BM28,BQ$1) -> 13 | BR28: =COUNTIF($F28:$BM28,BR$1) -> 5 | BS28: =COUNTIF($F28:$BM28,BS$1) -> 5 | BT28: =COUNTIF($F28:$BM28,BT$1) -> 6
A29: 26 | B29: 29 | C29: T6 | D29: Nguyễn Đình Nam | E29: Agent | F29: D | G29: D | H29: D | I29: D | J29: D | K29: 0 | L29: C | M29: C | N29: C | O29: C | P29: C | Q29: 0 | R29: H | S29: H | T29: H | U29: H | V29: H | W29: 0 | X29: B | Y29: B | Z29: B | AA29: B | AB29: B | AC29: B | AD29: 0 | AE29: B | AF29: B | AG29: B | AH29: B | AI29: B | AJ29: B | AK29: B | AL29: 0 | AM29: A | AN29: A | AO29: A | AP29: A | AQ29: A | AR29: 0 | AS29: A | AT29: A | AU29: A | AV29: A | AW29: A | AX29: A | AY29: A | AZ29: 0 | BA29: A | BB29: A | BC29: A | BD29: A | BE29: A | BF29: 0 | BG29: E | BH29: E | BI29: E | BJ29: E | BK29: E | BL29: E | BN29: =SUM(BP29:BT29) -> 46 | BO29: =COUNTIF($F29:$BM29,"0") -> 8 | BP29: =COUNTIF($F29:$BM29,BP$1) -> 17 | BQ29: =COUNTIF($F29:$BM29,BQ$1) -> 13 | BR29: =COUNTIF($F29:$BM29,BR$1) -> 5 | BS29: =COUNTIF($F29:$BM29,BS$1) -> 5 | BT29: =COUNTIF($F29:$BM29,BT$1) -> 6
A30: 27 | B30: 30 | C30: T6 | D30: Bùi Lập Duy | E30: Agent | F30: D | G30: D | H30: D | I30: D | J30: D | K30: 0 | L30: C | M30: C | N30: C | O30: C | P30: 0 | Q30: C | R30: C | S30: C | T30: C | U30: C | V30: C | W30: C | X30: 0 | Y30: B | Z30: B | AA30: B | AB30: B | AC30: B | AD30: 0 | AE30: B | AF30: B | AG30: B | AH30: B | AI30: B | AJ30: B | AK30: B | AL30: 0 | AM30: A | AN30: A | AO30: A | AP30: A | AQ30: A | AR30: 0 | AS30: A | AT30: A | AU30: A | AV30: A | AW30: A | AX30: A | AY30: A | AZ30: 0 | BA30: A | BB30: A | BC30: A | BD30: A | BE30: A | BF30: 0 | BG30: E | BH30: E | BI30: E | BJ30: E | BK30: E | BL30: E | BN30: =SUM(BP30:BT30) -> 51 | BO30: =COUNTIF($F30:$BM30,"0") -> 8 | BP30: =COUNTIF($F30:$BM30,BP$1) -> 17 | BQ30: =COUNTIF($F30:$BM30,BQ$1) -> 12 | BR30: =COUNTIF($F30:$BM30,BR$1) -> 11 | BS30: =COUNTIF($F30:$BM30,BS$1) -> 5 | BT30: =COUNTIF($F30:$BM30,BT$1) -> 6
A31: 28 | B31: 31 | C31: T7 | D31: Phạm Đỗ Duy Quang | E31: Agent | F31: C | G31: C | H31: C | I31: 0 | J31: C | K31: C | L31: C | M31: C | N31: C | O31: C | P31: C | Q31: 0 | R31: B | S31: B | T31: B | U31: B | V31: B | W31: B | X31: B | Y31: 0 | Z31: B | AA31: B | AB31: B | AC31: B | AD31: B | AE31: 0 | AF31: A | AG31: A | AH31: A | AI31: A | AJ31: A | AK31: 0 | AL31: A | AM31: A | AN31: A | AO31: A | AP31: A | AQ31: A | AR31: A | AS31: 0 | AT31: A | AU31: A | AV31: A | AW31: A | AX31: A | AY31: 0 | AZ31: E | BA31: E | BB31: E | BC31: E | BD31: E | BE31: E | BF31: E | BG31: 0 | BH31: E | BI31: E | BJ31: E | BK31: E | BL31: E | BN31: =SUM(BP31:BT31) -> 51 | BO31: =COUNTIF($F31:$BM31,"0") -> 8 | BP31: =COUNTIF($F31:$BM31,BP$1) -> 17 | BQ31: =COUNTIF($F31:$BM31,BQ$1) -> 12 | BR31: =COUNTIF($F31:$BM31,BR$1) -> 10 | BS31: =COUNTIF($F31:$BM31,BS$1) -> 0 | BT31: =COUNTIF($F31:$BM31,BT$1) -> 12
A32: 29 | B32: 32 | C32: T7 | D32: Trần Gia Huy | E32: Agent | F32: C | G32: C | H32: C | I32: 0 | J32: C | K32: C | L32: C | M32: C | N32: C | O32: C | P32: C | Q32: 0 | R32: B | S32: B | T32: B | U32: B | V32: B | W32: B | X32: B | Y32: 0 | Z32: B | AA32: B | AB32: B | AC32: B | AD32: B | AE32: 0 | AF32: A | AG32: A | AH32: A | AI32: A | AJ32: A | AK32: 0 | AL32: A | AM32: A | AN32: A | AO32: A | AP32: A | AQ32: A | AR32: A | AS32: 0 | AT32: A | AU32: A | AV32: A | AW32: A | AX32: A | AY32: 0 | AZ32: E | BA32: E | BB32: E | BC32: E | BD32: E | BE32: E | BF32: E | BG32: 0 | BH32: E | BI32: E | BJ32: E | BK32: E | BL32: E | BN32: =SUM(BP32:BT32) -> 51 | BO32: =COUNTIF($F32:$BM32,"0") -> 8 | BP32: =COUNTIF($F32:$BM32,BP$1) -> 17 | BQ32: =COUNTIF($F32:$BM32,BQ$1) -> 12 | BR32: =COUNTIF($F32:$BM32,BR$1) -> 10 | BS32: =COUNTIF($F32:$BM32,BS$1) -> 0 | BT32: =COUNTIF($F32:$BM32,BT$1) -> 12
A33: 30 | B33: 33 | C33: T7 | D33: Phạm Thị Hiền | E33: Agent | F33: C | G33: C | H33: C | I33: 0 | J33: C | K33: C | L33: C | M33: C | N33: C | O33: C | P33: C | Q33: 0 | R33: B | S33: B | T33: B | U33: B | V33: B | W33: B | X33: B | Y33: 0 | Z33: B | AA33: B | AB33: B | AC33: B | AD33: B | AE33: 0 | AF33: A | AG33: A | AH33: A | AI33: A | AJ33: A | AK33: A | AL33: 0 | AM33: A | AN33: A | AO33: A | AP33: A | AQ33: A | AR33: A | AS33: 0 | AT33: A | AU33: A | AV33: A | AW33: A | AX33: A | AY33: 0 | AZ33: E | BA33: E | BB33: E | BC33: E | BD33: E | BE33: E | BF33: E | BG33: 0 | BH33: E | BI33: E | BJ33: E | BK33: E | BL33: E | BN33: =SUM(BP33:BT33) -> 51 | BO33: =COUNTIF($F33:$BM33,"0") -> 8 | BP33: =COUNTIF($F33:$BM33,BP$1) -> 17 | BQ33: =COUNTIF($F33:$BM33,BQ$1) -> 12 | BR33: =COUNTIF($F33:$BM33,BR$1) -> 10 | BS33: =COUNTIF($F33:$BM33,BS$1) -> 0 | BT33: =COUNTIF($F33:$BM33,BT$1) -> 12
A34: 31 | B34: 34 | C34: T7 | D34: Hoàng Lạp Kim | E34: Agent | F34: C | G34: C | H34: C | I34: 0 | J34: C | K34: C | L34: C | M34: C | N34: C | O34: C | Q34: 0 | R34: H | S34: H | T34: H | U34: H | V34: H | W34: 0 | X34: B | Y34: B | Z34: B | AA34: B | AB34: B | AC34: B | AD34: B | AE34: 0 | AF34: A | AG34: A | AH34: A | AI34: A | AJ34: A | AK34: 0 | AL34: A | AM34: A | AN34: A | AO34: A | AP34: A | AQ34: A | AR34: A | AS34: 0 | AT34: A | AU34: A | AV34: A | AW34: A | AX34: A | AY34: 0 | AZ34: E | BA34: E | BB34: E | BC34: E | BD34: E | BE34: E | BF34: E | BG34: 0 | BH34: E | BI34: E | BJ34: E | BK34: E | BL34: E | BN34: =SUM(BP34:BT34) -> 45 | BO34: =COUNTIF($F34:$BM34,"0") -> 8 | BP34: =COUNTIF($F34:$BM34,BP$1) -> 17 | BQ34: =COUNTIF($F34:$BM34,BQ$1) -> 7 | BR34: =COUNTIF($F34:$BM34,BR$1) -> 9 | BS34: =COUNTIF($F34:$BM34,BS$1) -> 0 | BT34: =COUNTIF($F34:$BM34,BT$1) -> 12
A35: 32 | B35: 35 | C35: T7 | D35: Nguyễn Thành Nam | E35: Agent | F35: C | G35: C | H35: C | I35: 0 | J35: C | K35: C | L35: C | M35: C | N35: C | O35: C | P35: C | Q35: 0 | R35: H | S35: H | T35: H | U35: H | V35: H | W35: 0 | X35: B | Y35: B | Z35: B | AA35: B | AB35: B | AC35: B | AD35: B | AE35: 0 | AF35: A | AG35: A | AH35: A | AI35: A | AJ35: A | AK35: 0 | AL35: A | AM35: A | AN35: A | AO35: A | AP35: A | AQ35: A | AR35: A | AS35: 0 | AT35: A | AU35: A | AV35: A | AW35: A | AX35: A | AY35: 0 | AZ35: E | BA35: E | BB35: E | BC35: E | BD35: E | BE35: E | BF35: E | BG35: 0 | BH35: E | BI35: E | BJ35: E | BK35: E | BL35: E | BN35: =SUM(BP35:BT35) -> 46 | BO35: =COUNTIF($F35:$BM35,"0") -> 8 | BP35: =COUNTIF($F35:$BM35,BP$1) -> 17 | BQ35: =COUNTIF($F35:$BM35,BQ$1) -> 7 | BR35: =COUNTIF($F35:$BM35,BR$1) -> 10 | BS35: =COUNTIF($F35:$BM35,BS$1) -> 0 | BT35: =COUNTIF($F35:$BM35,BT$1) -> 12
A36: 33 | B36: 36 | C36: T8 | D36: Phan Trung Phong | E36: Agent | F36: C | G36: C | H36: C | I36: C | J36: 0 | K36: B | L36: B | M36: B | N36: B | O36: B | P36: B | Q36: 0 | R36: H | S36: H | T36: H | U36: H | V36: H | W36: 0 | X36: A | Y36: A | Z36: A | AA36: A | AB36: A | AC36: A | AD36: 0 | AE36: A | AF36: A | AG36: A | AH36: A | AI36: A | AJ36: A | AK36: A | AL36: 0 | AM36: E | AN36: E | AO36: E | AP36: E | AQ36: E | AR36: 0 | AS36: E | AT36: E | AU36: E | AV36: E | AW36: E | AX36: E | AY36: E | AZ36: 0 | BA36: E | BB36: E | BC36: E | BD36: E | BE36: E | BF36: 0 | BG36: D | BH36: D | BI36: D | BJ36: D | BK36: D | BL36: D | BN36: =SUM(BP36:BT36) -> 46 | BO36: =COUNTIF($F36:$BM36,"0") -> 8 | BP36: =COUNTIF($F36:$BM36,BP$1) -> 13 | BQ36: =COUNTIF($F36:$BM36,BQ$1) -> 6 | BR36: =COUNTIF($F36:$BM36,BR$1) -> 4 | BS36: =COUNTIF($F36:$BM36,BS$1) -> 6 | BT36: =COUNTIF($F36:$BM36,BT$1) -> 17
A37: 34 | B37: 37 | C37: T8 | D37: Nguyễn Hoàng Thiên Ân | E37: Agent | F37: C | G37: C | H37: C | I37: C | J37: 0 | K37: B | L37: B | M37: B | N37: B | O37: B | P37: 0 | Q37: B | R37: B | S37: B | T37: B | U37: B | V37: B | W37: B | X37: 0 | Y37: A | Z37: A | AA37: A | AB37: A | AC37: A | AD37: 0 | AE37: A | AF37: A | AG37: A | AH37: A | AI37: A | AJ37: A | AK37: A | AL37: 0 | AM37: E | AN37: E | AO37: E | AP37: E | AQ37: E | AR37: 0 | AS37: E | AT37: E | AU37: E | AV37: E | AW37: E | AX37: E | AY37: E | AZ37: 0 | BA37: E | BB37: E | BC37: E | BD37: E | BE37: E | BF37: 0 | BG37: D | BH37: D | BI37: D | BJ37: D | BK37: D | BL37: D | BN37: =SUM(BP37:BT37) -> 51 | BO37: =COUNTIF($F37:$BM37,"0") -> 8 | BP37: =COUNTIF($F37:$BM37,BP$1) -> 12 | BQ37: =COUNTIF($F37:$BM37,BQ$1) -> 12 | BR37: =COUNTIF($F37:$BM37,BR$1) -> 4 | BS37: =COUNTIF($F37:$BM37,BS$1) -> 6 | BT37: =COUNTIF($F37:$BM37,BT$1) -> 17
A38: 35 | B38: 38 | C38: T8 | D38: Nguyễn Trung Kiên | E38: Agent | F38: C | G38: C | H38: C | I38: C | J38: 0 | K38: B | L38: B | M38: B | N38: B | O38: B | P38: 0 | Q38: B | R38: B | S38: B | T38: B | U38: B | V38: B | W38: 0 | X38: A | Y38: A | Z38: A | AA38: A | AB38: A | AC38: A | AD38: 0 | AE38: A | AF38: A | AG38: A | AH38: A | AI38: A | AJ38: A | AK38: A | AL38: 0 | AM38: E | AN38: E | AO38: E | AP38: E | AQ38: E | AR38: 0 | AS38: E | AT38: E | AU38: E | AV38: E | AW38: E | AX38: E | AY38: E | AZ38: 0 | BA38: E | BB38: E | BC38: E | BD38: E | BE38: E | BF38: 0 | BG38: D | BH38: D | BI38: D | BJ38: D | BK38: D | BL38: D | BN38: =SUM(BP38:BT38) -> 51 | BO38: =COUNTIF($F38:$BM38,"0") -> 8 | BP38: =COUNTIF($F38:$BM38,BP$1) -> 13 | BQ38: =COUNTIF($F38:$BM38,BQ$1) -> 11 | BR38: =COUNTIF($F38:$BM38,BR$1) -> 4 | BS38: =COUNTIF($F38:$BM38,BS$1) -> 6 | BT38: =COUNTIF($F38:$BM38,BT$1) -> 17
A39: 36 | B39: 39 | C39: T8 | D39: Trần Trọng Tuấn | E39: Agent | F39: C | G39: C | H39: C | I39: C | J39: 0 | K39: B | L39: B | M39: B | N39: B | O39: B | P39: 0 | Q39: B | R39: B | S39: H | T39: H | U39: B | V39: B | W39: B | X39: 0 | Y39: A | Z39: A | AA39: A | AB39: A | AC39: A | AD39: 0 | AE39: A | AF39: A | AG39: A | AH39: A | AI39: A | AJ39: A | AK39: A | AL39: 0 | AM39: E | AN39: E | AO39: E | AP39: E | AQ39: E | AR39: 0 | AS39: E | AT39: E | AU39: E | AV39: E | AW39: E | AX39: E | AY39: E | AZ39: 0 | BA39: E | BB39: E | BC39: E | BD39: E | BE39: E | BF39: 0 | BG39: E | BH39: E | BI39: E | BJ39: E | BK39: E | BL39: E | BN39: =SUM(BP39:BT39) -> 49 | BO39: =COUNTIF($F39:$BM39,"0") -> 8 | BP39: =COUNTIF($F39:$BM39,BP$1) -> 12 | BQ39: =COUNTIF($F39:$BM39,BQ$1) -> 10 | BR39: =COUNTIF($F39:$BM39,BR$1) -> 4 | BS39: =COUNTIF($F39:$BM39,BS$1) -> 0 | BT39: =COUNTIF($F39:$BM39,BT$1) -> 23
A40: 37 | B40: 40 | C40: T8 | D40: Phan Thị Trúc Linh | E40: Agent | F40: C | G40: C | H40: C | I40: C | J40: 0 | K40: B | L40: B | M40: B | N40: B | O40: B | P40: 0 | Q40: B | R40: B | S40: B | T40: B | U40: B | V40: B | W40: 0 | X40: A | Y40: A | Z40: A | AA40: A | AB40: A | AC40: A | AD40: A | AE40: 0 | AF40: A | AG40: A | AH40: A | AI40: A | AJ40: A | AK40: A | AL40: 0 | AM40: E | AN40: E | AO40: E | AP40: E | AQ40: E | AR40: 0 | AS40: E | AT40: E | AU40: E | AV40: E | AW40: E | AX40: E | AY40: E | AZ40: 0 | BA40: E | BB40: E | BC40: E | BD40: E | BE40: E | BF40: 0 | BG40: D | BH40: D | BI40: D | BJ40: D | BK40: D | BL40: D | BN40: =SUM(BP40:BT40) -> 51 | BO40: =COUNTIF($F40:$BM40,"0") -> 8 | BP40: =COUNTIF($F40:$BM40,BP$1) -> 13 | BQ40: =COUNTIF($F40:$BM40,BQ$1) -> 11 | BR40: =COUNTIF($F40:$BM40,BR$1) -> 4 | BS40: =COUNTIF($F40:$BM40,BS$1) -> 6 | BT40: =COUNTIF($F40:$BM40,BT$1) -> 17
...

Sheet Schedule April_26
G1: 46106 | H1: 46107 | I1: 46108 | J1: 46109 | K1: 46110 | L1: 46111 | M1: 46112 | N1: 46113 | O1: 46114 | P1: 46115 | Q1: 46116 | R1: 46117 | S1: 46118 | T1: 46119 | U1: 46120 | V1: 46121 | W1: 46122 | X1: 46123 | Y1: 46124 | Z1: 46125 | AA1: 46126 | AB1: 46127 | AC1: 46128 | AD1: 46129 | AE1: 46130 | AF1: 46131 | AG1: 46132 | AH1: 46133 | AI1: 46134 | AJ1: 46135 | AK1: 46136 | AL1: 46137 | AM1: 46138 | AN1: 46139 | AO1: 46140 | AP1: 46141 | AQ1: 46142 | AR1: 46143 | AS1: 46144 | AT1: 46145 | AU1: 46146 | AV1: 46147 | AW1: 46148 | AX1: 46149 | AY1: 46150 | BA1: Workdays | BB1: Day off | BC1: A | BD1: B | BE1: C | BF1: D | BG1: E
A2: No. | B2: New | C2: NAME | E2: POSITION | F2: TIME START | G2: =CHOOSE(WEEKDAY(G1),"Sun","Mon","Tue","Wed","Thu","Fri","Sat") -> Wed | H2: =CHOOSE(WEEKDAY(H1),"Sun","Mon","Tue","Wed","Thu","Fri","Sat") -> Thu | I2: =CHOOSE(WEEKDAY(I1),"Sun","Mon","Tue","Wed","Thu","Fri","Sat") -> Fri | J2: =CHOOSE(WEEKDAY(J1),"Sun","Mon","Tue","Wed","Thu","Fri","Sat") -> Sat | K2: =CHOOSE(WEEKDAY(K1),"Sun","Mon","Tue","Wed","Thu","Fri","Sat") -> Sun | L2: =CHOOSE(WEEKDAY(L1),"Sun","Mon","Tue","Wed","Thu","Fri","Sat") -> Mon | M2: =CHOOSE(WEEKDAY(M1),"Sun","Mon","Tue","Wed","Thu","Fri","Sat") -> Tue | N2: =CHOOSE(WEEKDAY(N1),"Sun","Mon","Tue","Wed","Thu","Fri","Sat") -> Wed | ... AY2: =CHOOSE(WEEKDAY(AY1),"Sun","Mon","Tue","Wed","Thu","Fri","Sat") -> Fri
G3: =COUNTIF(G24:G122,"<>0") -> 95 | H3: =COUNTIF(H24:H122,"<>0") -> 95 | I3: =COUNTIF(I24:I122,"<>0") -> 95 | J3: =COUNTIF(J24:J122,"<>0") -> 56 | K3: =COUNTIF(K24:K122,"<>0") -> 47 | L3: =COUNTIF(L24:L122,"<>0") -> 87 | M3: =COUNTIF(M24:M122,"<>0") -> 95 | N3: =COUNTIF(N24:N122,"<>0") -> 95 | ... AY3: =COUNTIF(AY24:AY122,"<>0") -> 93
A4: 1 | B4: AT1 | C4: Phạm Đỗ Duy Quang | D4: quang.phamdoduy | E4: Agent | F4: 0 | G4: E | H4: E | I4: E | J4: E | K4: 0 | L4: E | M4: E | N4: E | O4: E | P4: E | Q4: 0 | R4: D | S4: D | T4: D | U4: D | V4: D | W4: D | X4: D | Y4: 0 | Z4: D | AA4: D | AB4: D | AC4: D | AD4: D | AE4: D | AF4: D | AG4: 0 | AH4: D | AI4: D | AJ4: D | AK4: D | AL4: D | AM4: 0 | AN4: D | AO4: D | AP4: D | AQ4: D | AR4: D | AS4: D | AT4: D | AU4: 0 | AV4: D | AW4: D | AX4: D | AY4: D | BA4: =SUM(BC4:BG4) -> 39 | BB4: =COUNTIF($G4:$AZ4,"0") -> 6 | BC4: =COUNTIF($G4:$AZ4,BC$1) -> 0 | BD4: =COUNTIF($G4:$AZ4,BD$1) -> 0 | BE4: =COUNTIF($G4:$AZ4,BE$1) -> 0 | BF4: =COUNTIF($G4:$AZ4,BF$1) -> 30 | BG4: =COUNTIF($G4:$AZ4,BG$1) -> 9
A5: 2 | B5: AT1 | C5: Trần Gia Huy | D5: huy.tran | E5: Agent | F5: 0 | G5: E | H5: E | I5: E | J5: E | K5: 0 | L5: E | M5: E | N5: E | O5: E | P5: E | Q5: 0 | R5: D | S5: D | T5: D | U5: D | V5: D | W5: D | X5: D | Y5: 0 | Z5: D | AA5: D | AB5: D | AC5: D | AD5: D | AE5: D | AF5: D | AG5: 0 | AH5: D | AI5: D | AJ5: D | AK5: D | AL5: D | AM5: 0 | AN5: D | AO5: D | AP5: D | AQ5: D | AR5: D | AS5: D | AT5: D | AU5: 0 | AV5: D | AW5: D | AX5: D | AY5: D | BA5: =SUM(BC5:BG5) -> 39 | BB5: =COUNTIF($G5:$AZ5,"0") -> 6 | BC5: =COUNTIF($G5:$AZ5,BC$1) -> 0 | BD5: =COUNTIF($G5:$AZ5,BD$1) -> 0 | BE5: =COUNTIF($G5:$AZ5,BE$1) -> 0 | BF5: =COUNTIF($G5:$AZ5,BF$1) -> 30 | BG5: =COUNTIF($G5:$AZ5,BG$1) -> 9
A6: 3 | B6: AT1 | C6: Hoàng Lạp Kim | D6: kim.hoanglap | E6: Agent | F6: 0 | G6: E | H6: E | I6: E | J6: E | K6: 0 | L6: E | M6: E | N6: E | O6: E | P6: E | Q6: 0 | R6: D | S6: D | T6: D | U6: D | V6: D | W6: D | X6: D | Y6: 0 | Z6: D | AA6: D | AB6: D | AC6: D | AD6: D | AE6: D | AF6: D | AG6: 0 | AH6: D | AI6: D | AJ6: D | AK6: D | AL6: D | AM6: 0 | AN6: D | AO6: D | AP6: D | AQ6: D | AR6: D | AS6: D | AT6: D | AU6: 0 | AV6: D | AW6: D | AX6: D | AY6: D | BA6: =SUM(BC6:BG6) -> 39 | BB6: =COUNTIF($G6:$AZ6,"0") -> 6 | BC6: =COUNTIF($G6:$AZ6,BC$1) -> 0 | BD6: =COUNTIF($G6:$AZ6,BD$1) -> 0 | BE6: =COUNTIF($G6:$AZ6,BE$1) -> 0 | BF6: =COUNTIF($G6:$AZ6,BF$1) -> 30 | BG6: =COUNTIF($G6:$AZ6,BG$1) -> 9
A7: 4 | B7: AT1 | C7: Nguyễn Thành Nam | D7: nam.nguyenthanh | E7: Agent | F7: 0 | G7: E | H7: E | I7: E | J7: E | K7: 0 | L7: E | M7: E | N7: E | O7: E | P7: E | Q7: 0 | R7: D | S7: D | T7: D | U7: D | V7: D | W7: D | X7: D | Y7: 0 | Z7: D | AA7: D | AB7: D | AC7: D | AD7: D | AE7: D | AF7: 0 | AG7: D | AH7: D | AI7: D | AJ7: D | AK7: D | AL7: D | AM7: D | AN7: 0 | AO7: D | AP7: D | AQ7: D | AR7: D | AS7: D | AT7: 0 | AU7: D | AV7: D | AW7: D | AX7: D | AY7: D | BA7: =SUM(BC7:BG7) -> 39 | BB7: =COUNTIF($G7:$AZ7,"0") -> 6 | BC7: =COUNTIF($G7:$AZ7,BC$1) -> 0 | BD7: =COUNTIF($G7:$AZ7,BD$1) -> 0 | BE7: =COUNTIF($G7:$AZ7,BE$1) -> 0 | BF7: =COUNTIF($G7:$AZ7,BF$1) -> 30 | BG7: =COUNTIF($G7:$AZ7,BG$1) -> 9
A8: 5 | B8: AT2 | C8: Phan Trung Phong | D8: phong.phantrung | E8: Agent | F8: 0 | G8: E | H8: E | I8: E | J8: 0 | K8: D | L8: D | M8: D | N8: D | O8: D | P8: D | Q8: D | R8: 0 | S8: D | T8: D | U8: D | V8: D | W8: D | X8: D | Y8: D | Z8: 0 | AA8: D | AB8: D | AC8: D | AD8: D | AE8: D | AF8: 0 | AG8: D | AH8: D | AI8: D | AJ8: D | AK8: D | AL8: D | AM8: 0 | AN8: D | AO8: D | AP8: D | AQ8: D | AR8: D | AS8: D | AT8: D | AU8: 0 | AV8: D | AW8: D | AX8: D | AY8: D | BA8: =SUM(BC8:BG8) -> 39 | BB8: =COUNTIF($G8:$AZ8,"0") -> 6 | BC8: =COUNTIF($G8:$AZ8,BC$1) -> 0 | BD8: =COUNTIF($G8:$AZ8,BD$1) -> 0 | BE8: =COUNTIF($G8:$AZ8,BE$1) -> 0 | BF8: =COUNTIF($G8:$AZ8,BF$1) -> 36 | BG8: =COUNTIF($G8:$AZ8,BG$1) -> 3
A9: 6 | B9: AT2 | C9: Nguyễn Hoàng Thiên Ân | D9: an.nguyen | E9: Agent | F9: 0 | G9: E | H9: E | I9: E | J9: 0 | K9: D | L9: D | M9: D | N9: D | O9: D | P9: D | Q9: D | R9: 0 | S9: D | T9: D | U9: D | V9: D | W9: D | X9: D | Y9: D | Z9: 0 | AA9: D | AB9: D | AC9: D | AD9: D | AE9: D | AF9: D | AG9: 0 | AH9: D | AI9: D | AJ9: D | AK9: D | AL9: D | AM9: 0 | AN9: D | AO9: D | AP9: D | AQ9: D | AR9: D | AS9: D | AT9: 0 | AU9: D | AV9: D | AW9: D | AX9: D | AY9: D | BA9: =SUM(BC9:BG9) -> 39 | BB9: =COUNTIF($G9:$AZ9,"0") -> 6 | BC9: =COUNTIF($G9:$AZ9,BC$1) -> 0 | BD9: =COUNTIF($G9:$AZ9,BD$1) -> 0 | BE9: =COUNTIF($G9:$AZ9,BE$1) -> 0 | BF9: =COUNTIF($G9:$AZ9,BF$1) -> 36 | BG9: =COUNTIF($G9:$AZ9,BG$1) -> 3
A10: 7 | B10: AT2 | C10: Nguyễn Trung Kiên | D10: kien.nguyen | E10: Agent | F10: 0 | G10: E | H10: E | I10: E | J10: 0 | K10: D | L10: D | M10: D | N10: D | O10: D | P10: D | Q10: D | R10: 0 | S10: D | T10: D | U10: D | V10: D | W10: D | X10: D | Y10: D | Z10: 0 | AA10: D | AB10: D | AC10: D | AD10: D | AE10: D | AF10: 0 | AG10: D | AH10: D | AI10: D | AJ10: D | AK10: D | AL10: D | AM10: 0 | AN10: D | AO10: D | AP10: D | AQ10: D | AR10: D | AS10: D | AT10: 0 | AU10: D | AV10: D | AW10: D | AX10: D | AY10: D | BA10: =SUM(BC10:BG10) -> 39 | BB10: =COUNTIF($G10:$AZ10,"0") -> 6 | BC10: =COUNTIF($G10:$AZ10,BC$1) -> 0 | BD10: =COUNTIF($G10:$AZ10,BD$1) -> 0 | BE10: =COUNTIF($G10:$AZ10,BE$1) -> 0 | BF10: =COUNTIF($G10:$AZ10,BF$1) -> 36 | BG10: =COUNTIF($G10:$AZ10,BG$1) -> 3
A11: 8 | B11: AT2 | C11: Trần Trọng Tuấn | D11: tuan.tran | E11: Agent | F11: 0.25 | G11: E | H11: E | I11: E | J11: 0 | K11: D | L11: D | M11: E | N11: E | O11: E | P11: E | Q11: E | R11: 0 | S11: E | T11: E | U11: E | V11: E | W11: E | X11: E | Y11: 0 | Z11: E | AA11: E | AB11: E | AC11: E | AD11: E | AE11: E | AF11: 0 | AG11: E | AH11: E | AI11: E | AJ11: E | AK11: E | AL11: 0 | AM11: E | AN11: E | AO11: E | AP11: E | AQ11: E | AR11: E | AS11: E | AT11: 0 | AU11: E | AV11: E | AW11: E | AX11: E | AY11: E | BA11: =SUM(BC11:BG11) -> 39 | BB11: =COUNTIF($G11:$AZ11,"0") -> 6 | BC11: =COUNTIF($G11:$AZ11,BC$1) -> 0 | BD11: =COUNTIF($G11:$AZ11,BD$1) -> 0 | BE11: =COUNTIF($G11:$AZ11,BE$1) -> 0 | BF11: =COUNTIF($G11:$AZ11,BF$1) -> 2 | BG11: =COUNTIF($G11:$AZ11,BG$1) -> 37
A12: 9 | B12: AT3 | C12: Nguyễn Thị Kim Chi | D12: chi.nguyen | E12: Sr Agent | F12: 0 | G12: D | H12: D | I12: D | J12: D | K12: 0 | L12: D | M12: D | N12: D | O12: D | P12: D | Q12: D | R12: D | S12: 0 | T12: D | U12: D | V12: D | W12: D | X12: D | Y12: D | Z12: 0 | AA12: D | AB12: D | AC12: D | AD12: D | AE12: D | AF12: 0 | AG12: E | AH12: E | AI12: E | AJ12: E | AK12: E | AL12: 0 | AM12: E | AN12: E | AO12: E | AP12: E | AQ12: E | AR12: E | AS12: E | AT12: 0 | AU12: E | AV12: E | AW12: E | AX12: E | AY12: E | BA12: =SUM(BC12:BG12) -> 39 | BB12: =COUNTIF($G12:$AZ12,"0") -> 6 | BC12: =COUNTIF($G12:$AZ12,BC$1) -> 0 | BD12: =COUNTIF($G12:$AZ12,BD$1) -> 0 | BE12: =COUNTIF($G12:$AZ12,BE$1) -> 0 | BF12: =COUNTIF($G12:$AZ12,BF$1) -> 22 | BG12: =COUNTIF($G12:$AZ12,BG$1) -> 17
A13: 10 | B13: AT3 | C13: Nguyễn Trần Khai Nguyên | D13: nguyen.nguyentran | E13: Agent | F13: 0 | G13: D | H13: D | I13: D | J13: D | K13: 0 | L13: D | M13: D | N13: D | O13: D | P13: D | Q13: D | R13: D | S13: 0 | T13: D | U13: D | V13: D | W13: D | X13: D | Y13: D | Z13: 0 | AA13: D | AB13: D | AC13: D | AD13: D | AE13: D | AF13: 0 | AG13: D | AH13: D | AI13: D | AJ13: D | AK13: D | AL13: D | AM13: D | AN13: 0 | AO13: D | AP13: D | AQ13: D | AR13: D | AS13: D | AT13: 0 | AU13: D | AV13: D | AW13: D | AX13: D | AY13: D | BA13: =SUM(BC13:BG13) -> 39 | BB13: =COUNTIF($G13:$AZ13,"0") -> 6 | BC13: =COUNTIF($G13:$AZ13,BC$1) -> 0 | BD13: =COUNTIF($G13:$AZ13,BD$1) -> 0 | BE13: =COUNTIF($G13:$AZ13,BE$1) -> 0 | BF13: =COUNTIF($G13:$AZ13,BF$1) -> 39 | BG13: =COUNTIF($G13:$AZ13,BG$1) -> 0
A14: 11 | B14: AT3 | C14: Hồ Trọng Thiện | D14: thien.ht | E14: Agent | F14: 0 | G14: A | H14: A | I14: A | J14: 0 | K14: E | L14: E | M14: E | N14: E | O14: E | P14: E | Q14: 0 | R14: D | S14: D | T14: D | U14: D | V14: D | W14: D | X14: D | Y14: 0 | Z14: D | AA14: D | AB14: D | AC14: D | AD14: D | AE14: D | AF14: D | AG14: 0 | AH14: D | AI14: D | AJ14: D | AK14: D | AL14: D | AM14: D | AN14: 0 | AO14: D | AP14: D | AQ14: D | AR14: D | AS14: D | AT14: 0 | AU14: D | AV14: D | AW14: D | AX14: D | AY14: D | BA14: =SUM(BC14:BG14) -> 39 | BB14: =COUNTIF($G14:$AZ14,"0") -> 6 | BC14: =COUNTIF($G14:$AZ14,BC$1) -> 3 | BD14: =COUNTIF($G14:$AZ14,BD$1) -> 0 | BE14: =COUNTIF($G14:$AZ14,BE$1) -> 0 | BF14: =COUNTIF($G14:$AZ14,BF$1) -> 30 | BG14: =COUNTIF($G14:$AZ14,BG$1) -> 6
A15: 12 | B15: AT3 | C15: Phan Thị Trúc Linh | D15: linh.ptt | E15: Agent | F15: 0 | G15: E | H15: E | I15: E | J15: 0 | K15: D | L15: D | M15: D | N15: D | O15: D | P15: D | Q15: D | R15: 0 | S15: D | T15: D | U15: D | V15: D | W15: D | X15: D | Y15: 0 | Z15: D | AA15: D | AB15: D | AC15: D | AD15: D | AE15: D | AF15: D | AG15: 0 | AH15: D | AI15: D | AJ15: D | AK15: D | AL15: D | AM15: D | AN15: 0 | AO15: D | AP15: D | AQ15: D | AR15: D | AS15: D | AT15: 0 | AU15: D | AV15: D | AW15: D | AX15: D | AY15: D | BA15: =SUM(BC15:BG15) -> 39 | BB15: =COUNTIF($G15:$AZ15,"0") -> 6 | BC15: =COUNTIF($G15:$AZ15,BC$1) -> 0 | BD15: =COUNTIF($G15:$AZ15,BD$1) -> 0 | BE15: =COUNTIF($G15:$AZ15,BE$1) -> 0 | BF15: =COUNTIF($G15:$AZ15,BF$1) -> 36 | BG15: =COUNTIF($G15:$AZ15,BG$1) -> 3
A16: 13 | B16: AT4 | C16: Nguyễn Hoàng Phú | D16: phu.nguyenhoang | E16: Agent | F16: 0.625 | G16: D | H16: D | I16: D | J16: D | K16: D | L16: 0 | M16: C | N16: C | O16: C | P16: C | Q16: C | R16: 0 | S16: A | T16: A | U16: A | V16: A | W16: A | X16: A | Y16: A | Z16: 0 | AA16: A | AB16: A | AC16: A | AD16: A | AE16: 0 | AF16: A | AG16: A | AH16: A | AI16: A | AJ16: A | AK16: A | AL16: A | AM16: 0 | AN16: A | AO16: A | AP16: A | AQ16: A | AR16: A | AS16: 0 | AT16: A | AU16: A | AV16: A | AW16: A | AX16: A | AY16: A | BA16: =SUM(BC16:BG16) -> 39 | BB16: =COUNTIF($G16:$AZ16,"0") -> 6 | BC16: =COUNTIF($G16:$AZ16,BC$1) -> 29 | BD16: =COUNTIF($G16:$AZ16,BD$1) -> 0 | BE16: =COUNTIF($G16:$AZ16,BE$1) -> 5 | BF16: =COUNTIF($G16:$AZ16,BF$1) -> 5 | BG16: =COUNTIF($G16:$AZ16,BG$1) -> 0
A17: 14 | B17: AT4 | C17: Nguyễn Thanh Phong | D17: phong.nguyen | E17: Agent | F17: 0.625 | G17: D | H17: D | I17: D | J17: D | K17: D | L17: 0 | M17: C | N17: C | O17: C | P17: C | Q17: C | R17: 0 | S17: A | T17: A | U17: A | V17: A | W17: A | X17: A | Y17: A | Z17: 0 | AA17: A | AB17: A | AC17: A | AD17: A | AE17: 0 | AF17: A | AG17: A | AH17: A | AI17: A | AJ17: A | AK17: A | AL17: A | AM17: 0 | AN17: A | AO17: A | AP17: A | AQ17: A | AR17: A | AS17: 0 | AT17: A | AU17: A | AV17: A | AW17: A | AX17: A | AY17: A | BA17: =SUM(BC17:BG17) -> 39 | BB17: =COUNTIF($G17:$AZ17,"0") -> 6 | BC17: =COUNTIF($G17:$AZ17,BC$1) -> 29 | BD17: =COUNTIF($G17:$AZ17,BD$1) -> 0 | BE17: =COUNTIF($G17:$AZ17,BE$1) -> 5 | BF17: =COUNTIF($G17:$AZ17,BF$1) -> 5 | BG17: =COUNTIF($G17:$AZ17,BG$1) -> 0
A18: 15 | B18: AT4 | C18: Ngô Diễm Thùy | D18: thuy.ngodiem | E18: Agent | F18: 0.625 | G18: D | H18: D | I18: D | J18: D | K18: D | L18: 0 | M18: C | N18: C | O18: C | P18: C | Q18: C | R18: 0 | S18: A | T18: A | U18: A | V18: A | W18: A | X18: A | Y18: A | Z18: 0 | AA18: A | AB18: A | AC18: A | AD18: A | AE18: 0 | AF18: A | AG18: A | AH18: A | AI18: A | AJ18: A | AK18: A | AL18: A | AM18: 0 | AN18: A | AO18: A | AP18: A | AQ18: A | AR18: A | AS18: 0 | AT18: A | AU18: A | AV18: A | AW18: A | AX18: A | AY18: A | BA18: =SUM(BC18:BG18) -> 39 | BB18: =COUNTIF($G18:$AZ18,"0") -> 6 | BC18: =COUNTIF($G18:$AZ18,BC$1) -> 29 | BD18: =COUNTIF($G18:$AZ18,BD$1) -> 0 | BE18: =COUNTIF($G18:$AZ18,BE$1) -> 5 | BF18: =COUNTIF($G18:$AZ18,BF$1) -> 5 | BG18: =COUNTIF($G18:$AZ18,BG$1) -> 0
A19: 16 | B19: AT4 | C19: Nguyễn Mai Việt Tính | D19: tinh.nguyenmaiviet | E19: Agent | F19: 0.625 | G19: B | H19: B | I19: B | J19: B | K19: 0 | L19: A | M19: A | N19: A | O19: A | P19: A | Q19: A | R19: 0 | S19: A | T19: A | U19: A | V19: A | W19: A | X19: A | Y19: 0 | Z19: A | AA19: A | AB19: A | AC19: A | AD19: A | AE19: 0 | AF19: A | AG19: A | AH19: A | AI19: A | AJ19: A | AK19: A | AL19: 0 | AM19: A | AN19: A | AO19: A | AP19: A | AQ19: A | AR19: A | AS19: 0 | AT19: A | AU19: A | AV19: A | AW19: A | AX19: A | AY19: A | BA19: =SUM(BC19:BG19) -> 39 | BB19: =COUNTIF($G19:$AZ19,"0") -> 6 | BC19: =COUNTIF($G19:$AZ19,BC$1) -> 35 | BD19: =COUNTIF($G19:$AZ19,BD$1) -> 4 | BE19: =COUNTIF($G19:$AZ19,BE$1) -> 0 | BF19: =COUNTIF($G19:$AZ19,BF$1) -> 0 | BG19: =COUNTIF($G19:$AZ19,BG$1) -> 0
A20: 17 | B20: AT5 | C20: Nguyễn Bảo Thái Tú | D20: tu.nbt | E20: Agent | F20: 0.625 | G20: C | H20: C | I20: C | J20: 0 | K20: C | L20: C | M20: C | N20: C | O20: C | P20: C | Q20: 0 | R20: A | S20: A | T20: A | U20: A | V20: A | W20: A | X20: 0 | Y20: A | Z20: A | AA20: A | AB20: A | AC20: A | AD20: A | AE20: A | AF20: 0 | AG20: A | AH20: A | AI20: A | AJ20: A | AK20: A | AL20: A | AM20: A | AN20: 0 | AO20: A | AP20: A | AQ20: A | AR20: A | AS20: A | AT20: 0 | AU20: A | AV20: A | AW20: A | AX20: A | AY20: A | BA20: =SUM(BC20:BG20) -> 39 | BB20: =COUNTIF($G20:$AZ20,"0") -> 6 | BC20: =COUNTIF($G20:$AZ20,BC$1) -> 30 | BD20: =COUNTIF($G20:$AZ20,BD$1) -> 0 | BE20: =COUNTIF($G20:$AZ20,BE$1) -> 9 | BF20: =COUNTIF($G20:$AZ20,BF$1) -> 0 | BG20: =COUNTIF($G20:$AZ20,BG$1) -> 0
A21: 18 | B21: AT5 | C21: Phạm Công Danh | D21: danh.phamcong | E21: Agent | F21: 0.625 | G21: C | H21: C | I21: C | J21: 0 | K21: C | L21: C | M21: C | N21: C | O21: C | P21: C | Q21: 0 | R21: A | S21: A | T21: A | U21: A | V21: A | W21: A | X21: 0 | Y21: A | Z21: A | AA21: A | AB21: A | AC21: A | AD21: A | AE21: A | AF21: 0 | AG21: A | AH21: A | AI21: A | AJ21: A | AK21: A | AL21: A | AM21: A | AN21: 0 | AO21: A | AP21: A | AQ21: A | AR21: A | AS21: A | AT21: 0 | AU21: A | AV21: A | AW21: A | AX21: A | AY21: A | BA21: =SUM(BC21:BG21) -> 39 | BB21: =COUNTIF($G21:$AZ21,"0") -> 6 | BC21: =COUNTIF($G21:$AZ21,BC$1) -> 30 | BD21: =COUNTIF($G21:$AZ21,BD$1) -> 0 | BE21: =COUNTIF($G21:$AZ21,BE$1) -> 9 | BF21: =COUNTIF($G21:$AZ21,BF$1) -> 0 | BG21: =COUNTIF($G21:$AZ21,BG$1) -> 0
A22: 19 | B22: AT5 | C22: Trần Thanh Hà | D22: thanhha.tran | E22: Sr Agent | F22: 0.625 | G22: C | H22: C | I22: C | J22: 0 | K22: C | L22: C | M22: C | N22: C | O22: C | P22: C | Q22: 0 | R22: A | S22: A | T22: A | U22: A | V22: A | W22: A | X22: 0 | Y22: A | Z22: A | AA22: A | AB22: A | AC22: A | AD22: A | AE22: A | AF22: 0 | AG22: A | AH22: A | AI22: A | AJ22: A | AK22: A | AL22: A | AM22: A | AN22: 0 | AO22: A | AP22: A | AQ22: A | AR22: A | AS22: A | AT22: 0 | AU22: A | AV22: A | AW22: A | AX22: A | AY22: A | BA22: =SUM(BC22:BG22) -> 39 | BB22: =COUNTIF($G22:$AZ22,"0") -> 6 | BC22: =COUNTIF($G22:$AZ22,BC$1) -> 30 | BD22: =COUNTIF($G22:$AZ22,BD$1) -> 0 | BE22: =COUNTIF($G22:$AZ22,BE$1) -> 9 | BF22: =COUNTIF($G22:$AZ22,BF$1) -> 0 | BG22: =COUNTIF($G22:$AZ22,BG$1) -> 0
A23: 20 | B23: AT5 | C23: Võ Hoàng Gia Bảo | D23: bao.vo | E23: Sr Agent | F23: 0.625 | G23: C | H23: C | I23: C | J23: 0 | K23: C | L23: C | M23: C | N23: C | O23: C | P23: C | Q23: 0 | R23: A | S23: A | T23: A | U23: A | V23: A | W23: A | X23: 0 | Y23: A | Z23: A | AA23: A | AB23: A | AC23: A | AD23: A | AE23: A | AF23: 0 | AG23: A | AH23: A | AI23: A | AJ23: A | AK23: A | AL23: A | AM23: A | AN23: 0 | AO23: A | AP23: A | AQ23: A | AR23: A | AS23: A | AT23: 0 | AU23: A | AV23: A | AW23: A | AX23: A | AY23: A | BA23: =SUM(BC23:BG23) -> 39 | BB23: =COUNTIF($G23:$AZ23,"0") -> 6 | BC23: =COUNTIF($G23:$AZ23,BC$1) -> 30 | BD23: =COUNTIF($G23:$AZ23,BD$1) -> 0 | BE23: =COUNTIF($G23:$AZ23,BE$1) -> 9 | BF23: =COUNTIF($G23:$AZ23,BF$1) -> 0 | BG23: =COUNTIF($G23:$AZ23,BG$1) -> 0
A24: 21 | B24: AT6 | C24: Nguyễn Quốc Duy | D24: duy.nguyenquoc | E24: Agent | F24: 0.625 | G24: C | H24: C | I24: C | J24: C | K24: 0 | L24: B | M24: B | N24: B | O24: B | P24: B | Q24: 0 | R24: A | S24: A | T24: A | U24: A | V24: A | W24: A | X24: A | Y24: 0 | Z24: A | AA24: A | AB24: A | AC24: A | AD24: A | AE24: A | AF24: A | AG24: 0 | AH24: A | AI24: A | AJ24: A | AK24: A | AL24: A | AM24: 0 | AN24: A | AO24: A | AP24: A | AQ24: A | AR24: A | AS24: 0 | AT24: A | AU24: A | AV24: A | AW24: A | AX24: A | AY24: A | BA24: =SUM(BC24:BG24) -> 39 | BB24: =COUNTIF($G24:$AZ24,"0") -> 6 | BC24: =COUNTIF($G24:$AZ24,BC$1) -> 30 | BD24: =COUNTIF($G24:$AZ24,BD$1) -> 5 | BE24: =COUNTIF($G24:$AZ24,BE$1) -> 4 | BF24: =COUNTIF($G24:$AZ24,BF$1) -> 0 | BG24: =COUNTIF($G24:$AZ24,BG$1) -> 0
A25: 22 | B25: AT6 | C25: Trương Thị Như Ngọc | D25: ngoc.truong | E25: Agent | F25: 0.625 | G25: C | H25: C | I25: C | J25: C | K25: 0 | L25: B | M25: B | N25: B | O25: B | P25: B | Q25: 0 | R25: A | S25: A | T25: A | U25: A | V25: A | W25: A | X25: A | Y25: 0 | Z25: A | AA25: A | AB25: A | AC25: A | AD25: A | AE25: A | AF25: A | AG25: 0 | AH25: A | AI25: A | AJ25: A | AK25: A | AL25: A | AM25: 0 | AN25: A | AO25: A | AP25: A | AQ25: A | AR25: A | AS25: 0 | AT25: A | AU25: A | AV25: A | AW25: A | AX25: A | AY25: A | BA25: =SUM(BC25:BG25) -> 39 | BB25: =COUNTIF($G25:$AZ25,"0") -> 6 | BC25: =COUNTIF($G25:$AZ25,BC$1) -> 30 | BD25: =COUNTIF($G25:$AZ25,BD$1) -> 5 | BE25: =COUNTIF($G25:$AZ25,BE$1) -> 4 | BF25: =COUNTIF($G25:$AZ25,BF$1) -> 0 | BG25: =COUNTIF($G25:$AZ25,BG$1) -> 0
A26: 23 | B26: AT6 | C26: Nguyễn Thành Quang | D26: quang.nguyenthanh | E26: Agent | F26: 0.625 | G26: C | H26: C | I26: C | J26: C | K26: 0 | L26: B | M26: B | N26: B | O26: B | P26: B | Q26: 0 | R26: A | S26: A | T26: A | U26: A | V26: A | W26: A | X26: A | Y26: 0 | Z26: A | AA26: A | AB26: A | AC26: A | AD26: A | AE26: A | AF26: A | AG26: 0 | AH26: A | AI26: A | AJ26: A | AK26: A | AL26: A | AM26: 0 | AN26: A | AO26: A | AP26: A | AQ26: A | AR26: A | AS26: 0 | AT26: A | AU26: A | AV26: A | AW26: A | AX26: A | AY26: A | BA26: =SUM(BC26:BG26) -> 39 | BB26: =COUNTIF($G26:$AZ26,"0") -> 6 | BC26: =COUNTIF($G26:$AZ26,BC$1) -> 30 | BD26: =COUNTIF($G26:$AZ26,BD$1) -> 5 | BE26: =COUNTIF($G26:$AZ26,BE$1) -> 4 | BF26: =COUNTIF($G26:$AZ26,BF$1) -> 0 | BG26: =COUNTIF($G26:$AZ26,BG$1) -> 0
A27: 24 | B27: AT6 | C27: Lưu Ngọc Mai | D27: mai.luungoc | E27: Agent | F27: 0.625 | G27: C | H27: C | I27: C | J27: C | K27: 0 | L27: B | M27: B | N27: B | O27: B | P27: B | Q27: 0 | R27: A | S27: A | T27: A | U27: A | V27: A | W27: A | X27: A | Y27: 0 | Z27: A | AA27: A | AB27: A | AC27: A | AD27: A | AE27: 0 | AF27: A | AG27: A | AH27: A | AI27: A | AJ27: A | AK27: A | AL27: A | AM27: 0 | AN27: A | AO27: A | AP27: A | AQ27: A | AR27: A | AS27: A | AT27: A | AU27: 0 | AV27: A | AW27: A | AX27: A | AY27: A | BA27: =SUM(BC27:BG27) -> 39 | BB27: =COUNTIF($G27:$AZ27,"0") -> 6 | BC27: =COUNTIF($G27:$AZ27,BC$1) -> 30 | BD27: =COUNTIF($G27:$AZ27,BD$1) -> 5 | BE27: =COUNTIF($G27:$AZ27,BE$1) -> 4 | BF27: =COUNTIF($G27:$AZ27,BF$1) -> 0 | BG27: =COUNTIF($G27:$AZ27,BG$1) -> 0
A28: 25 | B28: AT7 | C28: Lê Khương Duy | D28: duy.le | E28: Agent | F28: 0.375 | G28: B | H28: B | I28: B | J28: 0 | K28: B | L28: B | M28: B | N28: B | O28: B | P28: B | Q28: B | R28: 0 | S28: E | T28: E | U28: E | V28: E | W28: E | X28: E | Y28: 0 | Z28: E | AA28: E | AB28: E | AC28: E | AD28: D | AE28: 0 | AF28: D | AG28: D | AH28: D | AI28: D | AJ28: D | AK28: D | AL28: 0 | AM28: D | AN28: D | AO28: D | AP28: D | AQ28: D | AR28: D | AS28: D | AT28: 0 | AU28: D | AV28: D | AW28: D | AX28: D | AY28: D | BA28: =SUM(BC28:BG28) -> 39 | BB28: =COUNTIF($G28:$AZ28,"0") -> 6 | BC28: =COUNTIF($G28:$AZ28,BC$1) -> 0 | BD28: =COUNTIF($G28:$AZ28,BD$1) -> 10 | BE28: =COUNTIF($G28:$AZ28,BE$1) -> 0 | BF28: =COUNTIF($G28:$AZ28,BF$1) -> 19 | BG28: =COUNTIF($G28:$AZ28,BG$1) -> 10
A29: 26 | B29: AT7 | C29: Trần Hà Phương Uyên | D29: uyen.tran | E29: Agent | F29: 0.375 | G29: B | H29: B | I29: B | J29: 0 | K29: B | L29: B | M29: B | N29: B | O29: B | P29: B | Q29: B | R29: 0 | S29: E | T29: E | U29: E | V29: E | W29: E | X29: 0 | Y29: E | Z29: E | AA29: E | AB29: E | AC29: A | AD29: A | AE29: 0 | AF29: A | AG29: A | AH29: A | AI29: A | AJ29: A | AK29: A | AL29: 0 | AM29: A | AN29: A | AO29: A | AP29: A | AQ29: A | AR29: A | AS29: A | AT29: 0 | AU29: A | AV29: A | AW29: A | AX29: A | AY29: A | BA29: =SUM(BC29:BG29) -> 39 | BB29: =COUNTIF($G29:$AZ29,"0") -> 6 | BC29: =COUNTIF($G29:$AZ29,BC$1) -> 20 | BD29: =COUNTIF($G29:$AZ29,BD$1) -> 10 | BE29: =COUNTIF($G29:$AZ29,BE$1) -> 0 | BF29: =COUNTIF($G29:$AZ29,BF$1) -> 0 | BG29: =COUNTIF($G29:$AZ29,BG$1) -> 9
A30: 27 | B30: AT7 | C30: Vũ Đình Nguyễn | D30: nguyen.vudinh | E30: Agent | F30: 0.25 | G30: B | H30: B | I30: B | J30: 0 | K30: B | L30: B | M30: B | N30: B | O30: B | P30: B | Q30: B | R30: 0 | S30: E | T30: E | U30: E | V30: E | W30: E | X30: E | Y30: 0 | Z30: E | AA30: E | AB30: E | AC30: E | AD30: E | AE30: 0 | AF30: E | AG30: E | AH30: E | AI30: E | AJ30: E | AK30: E | AL30: E | AM30: 0 | AN30: E | AO30: E | AP30: E | AQ30: E | AR30: E | AS30: 0 | AT30: E | AU30: E | AV30: E | AW30: E | AX30: E | AY30: E | BA30: =SUM(BC30:BG30) -> 39 | BB30: =COUNTIF($G30:$AZ30,"0") -> 6 | BC30: =COUNTIF($G30:$AZ30,BC$1) -> 0 | BD30: =COUNTIF($G30:$AZ30,BD$1) -> 10 | BE30: =COUNTIF($G30:$AZ30,BE$1) -> 0 | BF30: =COUNTIF($G30:$AZ30,BF$1) -> 0 | BG30: =COUNTIF($G30:$AZ30,BG$1) -> 29
A31: 28 | B31: AT7 | C31: Ngô Minh Đức | D31: duc.ngominh | E31: Agent | F31: 0.25 | G31: B | H31: B | I31: B | J31: 0 | K31: B | L31: B | M31: B | N31: B | O31: B | P31: B | Q31: B | R31: 0 | S31: E | T31: E | U31: E | V31: E | W31: E | X31: E | Y31: 0 | Z31: E | AA31: E | AB31: E | AC31: E | AD31: E | AE31: 0 | AF31: E | AG31: E | AH31: E | AI31: E | AJ31: E | AK31: E | AL31: E | AM31: 0 | AN31: E | AO31: E | AP31: E | AQ31: E | AR31: E | AS31: 0 | AT31: E | AU31: E | AV31: E | AW31: E | AX31: E | AY31: E | BA31: =SUM(BC31:BG31) -> 39 | BB31: =COUNTIF($G31:$AZ31,"0") -> 6 | BC31: =COUNTIF($G31:$AZ31,BC$1) -> 0 | BD31: =COUNTIF($G31:$AZ31,BD$1) -> 10 | BE31: =COUNTIF($G31:$AZ31,BE$1) -> 0 | BF31: =COUNTIF($G31:$AZ31,BF$1) -> 0 | BG31: =COUNTIF($G31:$AZ31,BG$1) -> 29
A32: 29 | B32: AT8 | C32: Phan Hoàng Chin Na | D32: na.phc | E32: Agent | F32: 0.25 | G32: C | H32: C | I32: C | J32: C | K32: 0 | L32: B | M32: B | N32: B | O32: B | P32: B | Q32: 0 | R32: E | S32: E | T32: E | U32: E | V32: E | W32: E | X32: 0 | Y32: E | Z32: E | AA32: E | AB32: E | AC32: E | AD32: D | AE32: D | AF32: 0 | AG32: D | AH32: D | AI32: D | AJ32: D | AK32: D | AL32: D | AM32: D | AN32: 0 | AO32: D | AP32: D | AQ32: D | AR32: D | AS32: D | AT32: 0 | AU32: D | AV32: D | AW32: D | AX32: D | AY32: D | BA32: =SUM(BC32:BG32) -> 39 | BB32: =COUNTIF($G32:$AZ32,"0") -> 6 | BC32: =COUNTIF($G32:$AZ32,BC$1) -> 0 | BD32: =COUNTIF($G32:$AZ32,BD$1) -> 5 | BE32: =COUNTIF($G32:$AZ32,BE$1) -> 4 | BF32: =COUNTIF($G32:$AZ32,BF$1) -> 19 | BG32: =COUNTIF($G32:$AZ32,BG$1) -> 11
A33: 30 | B33: AT8 | C33: Trần Đình Tú | D33: dinhtu.tran | E33: Agent | F33: 0.375 | G33: B | H33: B | I33: B | J33: B | K33: 0 | L33: A | M33: A | N33: A | O33: A | P33: A | Q33: 0 | R33: E | S33: E | T33: E | U33: E | V33: E | W33: E | X33: 0 | Y33: E | Z33: E | AA33: E | AB33: E | AC33: A | AD33: A | AE33: A | AF33: 0 | AG33: A | AH33: A | AI33: A | AJ33: A | AK33: A | AL33: A | AM33: 0 | AN33: A | AO33: A | AP33: A | AQ33: A | AR33: A | AS33: A | AT33: A | AU33: 0 | AV33: A | AW33: A | AX33: A | AY33: A | BA33: =SUM(BC33:BG33) -> 39 | BB33: =COUNTIF($G33:$AZ33,"0") -> 6 | BC33: =COUNTIF($G33:$AZ33,BC$1) -> 25 | BD33: =COUNTIF($G33:$AZ33,BD$1) -> 4 | BE33: =COUNTIF($G33:$AZ33,BE$1) -> 0 | BF33: =COUNTIF($G33:$AZ33,BF$1) -> 0 | BG33: =COUNTIF($G33:$AZ33,BG$1) -> 10
