Workbook

Sheet DATA SAME VIN_202605
AO1: =COUNTIF(AO4:AO1008, "?*") -> 551 | AT1: =COUNTIF(AT4:AT1008, TRUE) -> 385 | AU1: =COUNTIF(AU4:AU1008, TRUE) -> 166 | AV1: =COUNTIF(AV4:AV1008, TRUE) -> 55
A2: Date | B2: LINK SESSION | C2: vin | D2: country | E2: model_year | F2: make | G2: model | H2: dsp_code | I2: delivery_station | J2: group_name | K2: account_name | L2: user_name | M2: session_key | N2: inspection_type | O2: inspection_status | P2: condition_report | Q2: inspection_create_datetime | R2: inspection_completion_datetime | S2: time_to_capture | T2: condition_report_completion_datetime | U2: condition_report_latency | V2: grading_standard | W2: total_chargeable_damage | X2: wtg_damages_left_side | Y2: wtg_damages_front_side | Z2: wtg_damages_right_side | AA2: wtg_damages_back_side | AB2: additional_chargeable_damages_left_side | AC2: additional_chargeable_damages_front_side | AD2: additional_chargeable_damages_right_side | AE2: additional_chargeable_damages_back_side | AF2: currency_type | AG2: low lighting | AH2: excessive brightness | AI2: blurred | AJ2: distance capture | AK2: shallow angle | AL2: poor framing | AM2: Note | AO2: Sessions | AP2: Reason | AQ2: Agent | AR2: QA | AS2: RE-CHECK & NOTE | AT2: Review ID Same Vin | AV2: Tick Miss/Repair
AT3: Đúng | AU3: Sai
A4: 0501-1hrs_NA | B4: {=IF(M4:M1008="","","https://agent-admin.paveapi.com/inspectionView/"&M4:M1008&"?activeTab=past-sessions")} -> https://agent-admin.paveapi.com/inspectionView/AMWT-VBAPZIS7EW?activeTab=past-sessions | C4: 1FTBR3X80MKA55750 | D4: US | E4: 2021 | F4: Ford | G4: Transit | H4: CAGT | I4: DFX3 | J4: DSP Accounts | K4: CAGT | L4: CAGT.user | M4: AMWT-VBAPZIS7EW | N4: Wear & Tear | O4: COMPLETE | P4: https://dashboard.paveapi.com/park/AMWT-VBAPZIS7EW/?l=en | Q4: 46144.002 | R4: 46144.007 | S4: 374 | T4: 46144.01 | U4: 1561 | V4: 2 | W4: 3210 | X4: 0 | Y4: 0 | Z4: 3 | AA4: 0 | AB4: 1 | AC4: 0 | AD4: 0 | AE4: 0 | AF4: USD | AG4: FALSE | AH4: FALSE | AI4: FALSE | AJ4: FALSE | AK4: FALSE | AL4: FALSE | AN4: {=IF(C4:C1008="","", IF(ROW(A4:A1008)=4, IF(A4<>"", DATE(2026, VALUE(LEFT(A4,2)), VALUE(MID(A4,3,2))), ""), IF(A4:A1008<>"", DATE(2026, VALUE(LEFT(A4:A1008,2)), VALUE(MID(A4:A1008,3,2))), LOOKUP(ROW(A4:A1008), ROW(A4:A1008)/(A4:A1008<>""), DATE(2026, VALUE(LEFT(A4:A1008,2)), VALUE(MID(A4:A1008,3,2))) ) ) ) )} -> 46143 | AO4: {=IF(M4:M1008<>"", M4:M1008, "")} -> AMWT-VBAPZIS7EW | AP4: QA Wrong damage | AR4: thien.ht | AS4: View 4: (3) Damage OLD xác định sai ( trầy nông) | AT4: FALSE | AU4: TRUE | AV4: FALSE
B5: https://agent-admin.paveapi.com/inspectionView/AMWT-4OBMFH3IF8?activeTab=past-sessions | C5: 1FTBR3X80MKA55750 | D5: US | E5: 2021 | F5: Ford | G5: Transit | H5: CAGT | I5: DFX3 | J5: DSP Accounts | K5: CAGT | L5: CAGT.user | M5: AMWT-4OBMFH3IF8 | N5: Wear & Tear | O5: COMPLETE | P5: https://dashboard.paveapi.com/park/AMWT-4OBMFH3IF8/?l=en | Q5: 46144.034 | R5: 46144.041 | S5: 546 | T5: 46144.045 | U5: 1164 | V5: 2 | W5: 2425 | X5: 0 | Y5: 0 | Z5: 3 | AA5: 0 | AB5: 0 | AC5: 0 | AD5: 0 | AE5: 0 | AF5: USD | AG5: FALSE | AH5: FALSE | AI5: FALSE | AJ5: FALSE | AK5: FALSE | AL5: FALSE | AM5: View 4: Remove wrong damage. / Correct one. | AN5: 46143 | AO5: AMWT-4OBMFH3IF8 | AT5: TRUE | AU5: FALSE | AV5: FALSE
B6: https://agent-admin.paveapi.com/inspectionView/AMWT-NL4VGUG6LA?activeTab=past-sessions | C6: 1FTBR3X83LKA48273 | D6: US | E6: 2020 | F6: Ford | G6: TRANSIT | H6: GOCZ | I6: WSV1 | J6: DSP Accounts | K6: GOCZ | L6: GOCZ.user | M6: AMWT-NL4VGUG6LA | N6: Fleet Improvement Fund | O6: COMPLETE | P6: https://dashboard.paveapi.com/park/AMWT-NL4VGUG6LA/?l=en | Q6: 46143.882 | R6: 46143.884 | S6: 109 | T6: 46143.891 | U6: 928 | V6: 2 | W6: 3860 | X6: 1 | Y6: 1 | Z6: 1 | AA6: 3 | AB6: 0 | AC6: 0 | AD6: 1 | AE6: 0 | AF6: USD | AG6: FALSE | AH6: FALSE | AI6: FALSE | AJ6: FALSE | AK6: FALSE | AL6: FALSE | AM6: / Correct one. | AN6: 46143 | AO6: AMWT-NL4VGUG6LA | AT6: TRUE | AU6: FALSE | AV6: FALSE
B7: https://agent-admin.paveapi.com/inspectionView/AMWT-BMUFW4BSCS?activeTab=past-sessions | C7: 1FTBR3X83LKA48273 | D7: US | E7: 2020 | F7: Ford | G7: TRANSIT | H7: GOCZ | I7: WSV1 | J7: DSP Accounts | K7: GOCZ | L7: GOCZ.user | M7: AMWT-BMUFW4BSCS | N7: Fleet Improvement Fund | O7: COMPLETE | P7: https://dashboard.paveapi.com/park/AMWT-BMUFW4BSCS/?l=en | Q7: 46143.912 | R7: 46143.914 | S7: 113 | T7: 46143.929 | U7: 1958 | V7: 3 | W7: 2675 | X7: 0 | Y7: 1 | Z7: 0 | AA7: 1 | AB7: 0 | AC7: 0 | AD7: 0 | AE7: 0 | AF7: USD | AG7: FALSE | AH7: FALSE | AI7: FALSE | AJ7: FALSE | AK7: FALSE | AL7: FALSE | AM7: View 4,7,8: Repaired. / Correct one. | AN7: 46143 | AO7: AMWT-BMUFW4BSCS | AT7: TRUE | AU7: FALSE | AV7: FALSE
B8: https://agent-admin.paveapi.com/inspectionView/AMWT-HMGVZGKD5B?activeTab=past-sessions | C8: 1FTBR3X83LKB04163 | D8: US | E8: 2020 | F8: Ford | G8: TRANSIT | H8: FRSN | I8: DSJ5 | J8: DSP Accounts | K8: FRSN | L8: SA2020 | M8: AMWT-HMGVZGKD5B | N8: Wear & Tear | O8: COMPLETE | P8: https://dashboard.paveapi.com/park/AMWT-HMGVZGKD5B/?l=en | Q8: 46143.926 | R8: 46143.927 | S8: 108 | T8: 46143.938 | U8: 4199 | V8: 4 | W8: 1755 | X8: 0 | Y8: 2 | Z8: 1 | AA8: 2 | AB8: 0 | AC8: 0 | AD8: 0 | AE8: 0 | AF8: USD | AG8: FALSE | AH8: FALSE | AI8: FALSE | AJ8: FALSE | AK8: FALSE | AL8: FALSE | AN8: 46143 | AO8: AMWT-HMGVZGKD5B | AS8: View 5: (2) Damage OLD kích thước nhỏ / Hình tối -> skip | AT8: FALSE | AU8: TRUE | AV8: FALSE
B9: https://agent-admin.paveapi.com/inspectionView/AMWT-FNK0WP6LGZ?activeTab=past-sessions | C9: 1FTBR3X83LKB04163 | D9: US | E9: 2020 | F9: Ford | G9: Transit | H9: FRSN | I9: DSJ5 | J9: DSP Accounts | K9: FRSN | L9: SA2020 | M9: AMWT-FNK0WP6LGZ | N9: Fleet Improvement Fund | O9: COMPLETE | P9: https://dashboard.paveapi.com/park/AMWT-FNK0WP6LGZ/?l=en | Q9: 46143.937 | R9: 46143.938 | S9: 91 | T9: 46143.951 | U9: 1263 | V9: 5 | W9: 970 | X9: 0 | Y9: 1 | Z9: 1 | AA9: 2 | AB9: 0 | AC9: 0 | AD9: 0 | AE9: 0 | AF9: USD | AG9: FALSE | AH9: FALSE | AI9: FALSE | AJ9: FALSE | AK9: FALSE | AL9: FALSE | AM9: View 5: Remove false positive damage. / Correct one. | AN9: 46143 | AO9: AMWT-FNK0WP6LGZ | AT9: TRUE | AU9: FALSE | AV9: FALSE
B10: https://agent-admin.paveapi.com/inspectionView/AMUO-MF9LWCXEZ8?activeTab=past-sessions | C10: 1FTBR3X85LKA87351 | D10: US | E10: 2020 | F10: Ford | G10: Transit | H10: AMZL | I10: AMZL | J10: Last Mile Rentals | K10: AMZL | M10: AMUO-MF9LWCXEZ8 | N10: Merchants_LMR_rtinsp | O10: COMPLETE | P10: https://dashboard.paveapi.com/park/AMUO-MF9LWCXEZ8/?l=en | Q10: 46143.542 | R10: 46143.544 | S10: 62 | T10: 46143.551 | U10: 788 | V10: 1 | W10: 14107.5 | X10: 6 | Y10: 7 | Z10: 11 | AA10: 2 | AB10: 2 | AC10: 0 | AD10: 0 | AE10: 0 | AF10: USD | AG10: FALSE | AH10: FALSE | AI10: FALSE | AJ10: FALSE | AK10: FALSE | AL10: FALSE | AN10: 46143 | AO10: AMUO-MF9LWCXEZ8 | AT10: TRUE | AU10: FALSE | AV10: FALSE
B11: https://agent-admin.paveapi.com/inspectionView/AMUO-NZVU2F1CVE?activeTab=past-sessions | C11: 1FTBR3X85LKA87351 | D11: US | E11: 2020 | F11: Ford | G11: Transit | H11: AMZL | I11: AMZL | J11: Last Mile Rentals | K11: AMZL | M11: AMUO-NZVU2F1CVE | N11: Merchants_LMR_rtinsp | O11: COMPLETE | P11: https://dashboard.paveapi.com/park/AMUO-NZVU2F1CVE/?l=en | Q11: 46143.554 | R11: 46143.555 | S11: 55 | T11: 46143.564 | U11: 1146 | V11: 1 | W11: 11022.5 | X11: 5 | Y11: 5 | Z11: 8 | AA11: 2 | AB11: 2 | AC11: 0 | AD11: 0 | AE11: 0 | AF11: USD | AG11: FALSE | AH11: FALSE | AI11: FALSE | AJ11: FALSE | AK11: FALSE | AL11: FALSE | AM11: View 4,5,7: Remove false positive damages. / Correct one. | AN11: 46143 | AO11: AMUO-NZVU2F1CVE | AT11: TRUE | AU11: FALSE | AV11: FALSE
B12: https://agent-admin.paveapi.com/inspectionView/AMWT-W31OGJODIC?activeTab=past-sessions | C12: 1FTBR3X88LKA47281 | D12: US | E12: 2020 | F12: Ford | G12: Transit | H12: AMZL | I12: AMZL | J12: Fleet Management Companies | K12: AMZL | L12: raffiautobody | M12: AMWT-W31OGJODIC | N12: Vehicle Pre-Repair | O12: COMPLETE | P12: https://dashboard.paveapi.com/park/AMWT-W31OGJODIC/?l=en | Q12: 46143.821 | R12: 46143.823 | S12: 167 | T12: 46143.831 | U12: 957 | V12: 3 | W12: 6295 | X12: 5 | Y12: 0 | Z12: 4 | AA12: 0 | AB12: 0 | AC12: 0 | AD12: 0 | AE12: 0 | AF12: USD | AG12: FALSE | AH12: FALSE | AI12: FALSE | AJ12: FALSE | AK12: FALSE | AL12: FALSE | AN12: 46143 | AO12: AMWT-W31OGJODIC | AT12: TRUE | AU12: FALSE | AV12: FALSE
B13: https://agent-admin.paveapi.com/inspectionView/AMWT-BYCPD7THNO?activeTab=past-sessions | C13: 1FTBR3X88LKA47281 | D13: US | E13: 2020 | F13: Ford | G13: TRANSIT | H13: AMZL | I13: AMZL | J13: Fleet Management Companies | K13: AMZL | L13: raffiautobody | M13: AMWT-BYCPD7THNO | N13: Vehicle Pre-Repair | O13: COMPLETE | P13: https://dashboard.paveapi.com/park/AMWT-BYCPD7THNO/?l=en | Q13: 46143.851 | R13: 46143.852 | S13: 96 | T13: 46143.858 | U13: 708 | V13: 2 | W13: 5595 | X13: 4 | Y13: 0 | Z13: 4 | AA13: 0 | AB13: 0 | AC13: 0 | AD13: 0 | AE13: 0 | AF13: USD | AG13: FALSE | AH13: FALSE | AI13: FALSE | AJ13: FALSE | AK13: FALSE | AL13: FALSE | AM13: View 4: Remove wrong damage. / Correct one. | AN13: 46143 | AO13: AMWT-BYCPD7THNO | AT13: TRUE | AU13: FALSE | AV13: FALSE
B14: https://agent-admin.paveapi.com/inspectionView/AMWT-ACX2LE9CUE?activeTab=past-sessions | C14: 1FTBR3X89LKA28805 | D14: US | E14: 2020 | F14: Ford | G14: Transit | H14: KRUS | I14: DXH1 | J14: DSP Accounts | K14: KRUS | L14: KRUS | M14: AMWT-ACX2LE9CUE | N14: Fleet Improvement Fund | O14: COMPLETE | P14: https://dashboard.paveapi.com/park/AMWT-ACX2LE9CUE/?l=en | Q14: 46143.865 | R14: 46143.866 | S14: 92 | T14: 46143.869 | U14: 475 | V14: 2 | W14: 3550 | X14: 0 | Y14: 1 | Z14: 3 | AA14: 0 | AB14: 1 | AC14: 0 | AD14: 2 | AE14: 0 | AF14: USD | AG14: FALSE | AH14: FALSE | AI14: FALSE | AJ14: FALSE | AK14: FALSE | AL14: FALSE | AN14: 46143 | AO14: AMWT-ACX2LE9CUE | AP14: QA Wrong damage | AR14: vi.votuan | AS14: View 7: (5, 6) Damage OLD đã sửa chữa | AT14: FALSE | AU14: TRUE | AV14: TRUE
B15: https://agent-admin.paveapi.com/inspectionView/AMWT-DQYDI0XVDF?activeTab=past-sessions | C15: 1FTBR3X89LKA28805 | D15: US | E15: 2020 | F15: Ford | G15: TRANSIT | H15: KRUS | I15: DXH1 | J15: DSP Accounts | K15: KRUS | L15: KRUS | M15: AMWT-DQYDI0XVDF | N15: Fleet Improvement Fund | O15: COMPLETE | P15: https://dashboard.paveapi.com/park/AMWT-DQYDI0XVDF/?l=en | Q15: 46143.873 | R15: 46143.877 | S15: 313 | T15: 46143.895 | U15: 1923 | V15: 2 | W15: 2075 | X15: 0 | Y15: 1 | Z15: 1 | AA15: 0 | AB15: 1 | AC15: 0 | AD15: 2 | AE15: 0 | AF15: USD | AG15: FALSE | AH15: FALSE | AI15: FALSE | AJ15: FALSE | AK15: FALSE | AL15: FALSE | AM15: View 7: Remove wrong damages. / Correct one. | AN15: 46143 | AO15: AMWT-DQYDI0XVDF | AT15: TRUE | AU15: FALSE | AV15: FALSE
B16: https://agent-admin.paveapi.com/inspectionView/AMWT-KJMUSXZ7TY?activeTab=past-sessions | C16: 1FTBR3X89LKA28805 | D16: US | E16: 2020 | F16: Ford | G16: TRANSIT | H16: KRUS | I16: DXH1 | J16: DSP Accounts | K16: KRUS | L16: KRUS | M16: AMWT-KJMUSXZ7TY | N16: Fleet Improvement Fund | O16: COMPLETE | P16: https://dashboard.paveapi.com/park/AMWT-KJMUSXZ7TY/?l=en | Q16: 46143.906 | R16: 46143.911 | S16: 390 | T16: 46143.928 | U16: 1929 | V16: 2 | W16: 2075 | X16: 0 | Y16: 1 | Z16: 1 | AA16: 0 | AB16: 1 | AC16: 0 | AD16: 2 | AE16: 0 | AF16: USD | AG16: FALSE | AH16: FALSE | AI16: FALSE | AJ16: FALSE | AK16: FALSE | AL16: FALSE | AN16: 46143 | AO16: AMWT-KJMUSXZ7TY | AT16: TRUE | AU16: FALSE | AV16: FALSE
B17: https://agent-admin.paveapi.com/inspectionView/AMWT-JBR590RVH4?activeTab=past-sessions | C17: 1FTYR3XM7KKB12644 | D17: US | E17: 2019 | F17: Ford | G17: Transit | H17: AMZL | I17: AMZL | J17: DSP Accounts | K17: AMZL | L17: Hussein94577 | M17: AMWT-JBR590RVH4 | N17: Fleet Improvement Fund | O17: COMPLETE | P17: https://dashboard.paveapi.com/park/AMWT-JBR590RVH4/?l=en | Q17: 46143.835 | R17: 46143.837 | S17: 181 | T17: 46143.84 | U17: 252511 | V17: 3 | W17: 2310 | X17: 2 | Y17: 1 | Z17: 0 | AA17: 0 | AB17: 1 | AC17: 0 | AD17: 0 | AE17: 0 | AF17: USD | AG17: FALSE | AH17: FALSE | AI17: FALSE | AJ17: FALSE | AK17: FALSE | AL17: FALSE | AM17: / Correct one. | AN17: 46143 | AO17: AMWT-JBR590RVH4 | AT17: TRUE | AU17: FALSE | AV17: FALSE
B18: https://agent-admin.paveapi.com/inspectionView/AMWT-BYBSVJ7MTV?activeTab=past-sessions | C18: 1FTYR3XM7KKB12644 | D18: US | E18: 2019 | F18: Ford | G18: Transit | H18: AMZL | I18: AMZL | J18: DSP Accounts | K18: AMZL | L18: Hussein94577 | M18: AMWT-BYBSVJ7MTV | N18: Fleet Improvement Fund | O18: COMPLETE | P18: https://dashboard.paveapi.com/park/AMWT-BYBSVJ7MTV/?l=en | Q18: 46143.863 | R18: 46143.865 | S18: 188 | T18: 46143.869 | U18: 254995 | V18: 3 | W18: 2310 | X18: 2 | Y18: 1 | Z18: 0 | AA18: 0 | AB18: 1 | AC18: 0 | AD18: 0 | AE18: 0 | AF18: USD | AG18: FALSE | AH18: FALSE | AI18: FALSE | AJ18: FALSE | AK18: FALSE | AL18: FALSE | AN18: 46143 | AO18: AMWT-BYBSVJ7MTV | AT18: TRUE | AU18: FALSE | AV18: FALSE
B19: https://agent-admin.paveapi.com/inspectionView/AMWT-MLBRUSHOFS?activeTab=past-sessions | C19: 1FTYR3XM7KKB12644 | D19: US | E19: 2019 | F19: Ford | G19: TRANSIT | H19: AMZL | I19: AMZL | J19: DSP Accounts | K19: AMZL | L19: Hussein94577 | M19: AMWT-MLBRUSHOFS | N19: Fleet Improvement Fund | O19: COMPLETE | P19: https://dashboard.paveapi.com/park/AMWT-MLBRUSHOFS/?l=en | Q19: 46143.879 | R19: 46143.881 | S19: 180 | T19: 46143.894 | U19: 1739 | V19: 4 | W19: 2235 | X19: 2 | Y19: 1 | Z19: 0 | AA19: 0 | AB19: 0 | AC19: 0 | AD19: 0 | AE19: 0 | AF19: USD | AG19: FALSE | AH19: FALSE | AI19: FALSE | AJ19: FALSE | AK19: FALSE | AL19: FALSE | AM19: View 4: Repaired. / Correct one. | AN19: 46143 | AO19: AMWT-MLBRUSHOFS | AT19: TRUE | AU19: FALSE | AV19: FALSE
B20: https://agent-admin.paveapi.com/inspectionView/AMWT-PJECSLAH7G?activeTab=past-sessions | C20: 3C6URVJG3LE136769 | D20: US | E20: 2020 | F20: Ram | G20: PROMASTER | H20: MVRK | I20: DNJ4 | J20: DSP Accounts | K20: MVRK | L20: MVRK.user | M20: AMWT-PJECSLAH7G | N20: Fleet Improvement Fund | O20: COMPLETE | P20: https://dashboard.paveapi.com/park/AMWT-PJECSLAH7G/?l=en | Q20: 46143.746 | R20: 46143.755 | S20: 700 | T20: 46143.758 | U20: 6953 | V20: 1 | W20: 12490 | X20: 9 | Y20: 3 | Z20: 12 | AA20: 0 | AB20: 1 | AC20: 0 | AD20: 1 | AE20: 0 | AF20: USD | AG20: FALSE | AH20: FALSE | AI20: FALSE | AJ20: FALSE | AK20: FALSE | AL20: FALSE | AN20: 46143 | AO20: AMWT-PJECSLAH7G | AP20: QA Wrong damage | AR20: nguyen.nguyentran | AS20: View 4: (1 2, 3, 4, 5, 6, 7, 9, 10) Damage OLD đã sửa chữa View 5: (1) Damage OLD xác định sai View 7: (1, 4, 5, 7) Damage OLD xác định sai | AT20: FALSE | AU20: TRUE | AV20: TRUE
B21: https://agent-admin.paveapi.com/inspectionView/AMWT-Q25QUFQA7Z?activeTab=past-sessions | C21: 3C6URVJG3LE136769 | D21: US | E21: 2020 | F21: Ram | G21: ProMaster | H21: MVRK | I21: DNJ4 | J21: DSP Accounts | K21: MVRK | L21: MVRK.user | M21: AMWT-Q25QUFQA7Z | N21: Fleet Improvement Fund | O21: COMPLETE | P21: https://dashboard.paveapi.com/park/AMWT-Q25QUFQA7Z/?l=en | Q21: 46143.777 | R21: 46143.788 | S21: 959 | T21: 46143.798 | U21: 2445 | V21: 2 | W21: 8980 | X21: 4 | Y21: 2 | Z21: 10 | AA21: 0 | AB21: 0 | AC21: 0 | AD21: 0 | AE21: 0 | AF21: USD | AG21: FALSE | AH21: FALSE | AI21: FALSE | AJ21: FALSE | AK21: FALSE | AL21: FALSE | AM21: View 4,5: Remove wrong damages. / Correct one. View 7: Remove wrong damages and adjust wrong name (26) / Correct one. | AN21: 46143 | AO21: AMWT-Q25QUFQA7Z | AT21: TRUE | AU21: FALSE | AV21: FALSE
B22: https://agent-admin.paveapi.com/inspectionView/AMWT-IMURJEZWXO?activeTab=past-sessions | C22: 3C6URVJG3LE136769 | D22: US | E22: 2020 | F22: Ram | G22: ProMaster | H22: MVRK | I22: DNJ4 | J22: DSP Accounts | K22: MVRK | L22: MVRK.user | M22: AMWT-IMURJEZWXO | N22: Fleet Improvement Fund | O22: COMPLETE | P22: https://dashboard.paveapi.com/park/AMWT-IMURJEZWXO/?l=en | Q22: 46143.86 | R22: 46143.861 | S22: 108 | T22: 46143.867 | U22: 2252 | V22: 2 | W22: 5512 | X22: 2 | Y22: 2 | Z22: 4 | AA22: 0 | AB22: 0 | AC22: 0 | AD22: 0 | AE22: 0 | AF22: USD | AG22: FALSE | AH22: FALSE | AI22: FALSE | AJ22: FALSE | AK22: FALSE | AL22: FALSE | AM22: View 4,7: Repaired. / Correct one. | AN22: 46143 | AO22: AMWT-IMURJEZWXO | AT22: TRUE | AU22: FALSE | AV22: FALSE
B23: https://agent-admin.paveapi.com/inspectionView/AMWT-OFS8PILHQT?activeTab=past-sessions | C23: 3C6URVJG3LE136769 | D23: US | E23: 2020 | F23: Ram | G23: ProMaster | H23: MVRK | I23: DNJ4 | J23: DSP Accounts | K23: MVRK | L23: MVRK.user | M23: AMWT-OFS8PILHQT | N23: Fleet Improvement Fund | O23: COMPLETE | P23: https://dashboard.paveapi.com/park/AMWT-OFS8PILHQT/?l=en | Q23: 46143.875 | R23: 46143.876 | S23: 126 | T23: 46143.885 | U23: 1435 | V23: 2 | W23: 4137 | X23: 2 | Y23: 2 | Z23: 3 | AA23: 0 | AB23: 0 | AC23: 0 | AD23: 0 | AE23: 0 | AF23: USD | AG23: FALSE | AH23: FALSE | AI23: FALSE | AJ23: FALSE | AK23: FALSE | AL23: FALSE | AM23: View 7: DSP covered the damage. | AN23: 46143 | AO23: AMWT-OFS8PILHQT | AT23: TRUE | AU23: FALSE | AV23: FALSE
B24: https://agent-admin.paveapi.com/inspectionView/AMWT-VR4XPMOLN5?activeTab=past-sessions | C24: 3C6URVJG3LE136769 | D24: US | E24: 2020 | F24: Ram | G24: ProMaster | H24: MVRK | I24: DNJ4 | J24: DSP Accounts | K24: MVRK | L24: MVRK.user | M24: AMWT-VR4XPMOLN5 | N24: Fleet Improvement Fund | O24: COMPLETE | P24: https://dashboard.paveapi.com/park/AMWT-VR4XPMOLN5/?l=en | Q24: 46143.89 | R24: 46143.892 | S24: 83 | T24: 46143.944 | U24: 5052 | V24: 3 | W24: 3330 | X24: 0 | Y24: 2 | Z24: 3 | AA24: 0 | AB24: 0 | AC24: 0 | AD24: 0 | AE24: 0 | AF24: USD | AG24: FALSE | AH24: FALSE | AI24: FALSE | AJ24: FALSE | AK24: FALSE | AL24: FALSE | AM24: View 4,7: Repaired. / Correct one. | AN24: 46143 | AO24: AMWT-VR4XPMOLN5 | AT24: TRUE | AU24: FALSE | AV24: FALSE
B25: https://agent-admin.paveapi.com/inspectionView/AMWT-M5TYMRIXHD?activeTab=past-sessions | C25: 3C6URVJG3LE136769 | D25: US | E25: 2020 | F25: Ram | G25: PROMASTER | H25: MVRK | I25: DNJ4 | J25: DSP Accounts | K25: MVRK | L25: MVRK.user | M25: AMWT-M5TYMRIXHD | N25: Fleet Improvement Fund | O25: COMPLETE | P25: https://dashboard.paveapi.com/park/AMWT-M5TYMRIXHD/?l=en | Q25: 46143.914 | R25: 46143.915 | S25: 120 | T25: 46143.952 | U25: 3746 | V25: 3 | W25: 3330 | X25: 0 | Y25: 2 | Z25: 3 | AA25: 0 | AB25: 0 | AC25: 0 | AD25: 0 | AE25: 0 | AF25: USD | AG25: FALSE | AH25: FALSE | AI25: FALSE | AJ25: FALSE | AK25: FALSE | AL25: FALSE | AN25: 46143 | AO25: AMWT-M5TYMRIXHD | AT25: TRUE | AU25: FALSE | AV25: FALSE
B26: https://agent-admin.paveapi.com/inspectionView/AMRR-PAO74CSSAJ?activeTab=past-sessions | C26: 3C6URVJG7LE140520 | D26: US | E26: 2020 | F26: Ram | G26: ProMaster | H26: MLKT | I26: WSC2 | J26: DSP Accounts | K26: MLKT | L26: lpolanco.mklt | M26: AMRR-PAO74CSSAJ | N26: Redeployment/Retirement | O26: COMPLETE | P26: https://dashboard.paveapi.com/park/AMRR-PAO74CSSAJ/?l=en | Q26: 46143.492 | R26: 46143.493 | S26: 124 | T26: 46143.496 | U26: 857 | V26: 2 | W26: 4060 | X26: 3 | Y26: 0 | Z26: 2 | AA26: 0 | AB26: 0 | AC26: 0 | AD26: 0 | AE26: 0 | AF26: USD | AG26: FALSE | AH26: FALSE | AI26: FALSE | AJ26: FALSE | AK26: FALSE | AL26: FALSE | AN26: 46143 | AO26: AMRR-PAO74CSSAJ | AT26: TRUE | AU26: FALSE | AV26: FALSE
B27: https://agent-admin.paveapi.com/inspectionView/AMWT-CCI6FFYO7W?activeTab=past-sessions | C27: 3C6URVJG7LE140520 | D27: US | E27: 2020 | F27: Ram | G27: PROMASTER | H27: MLKT | I27: WSC2 | J27: DSP Accounts | K27: MLKT | L27: lpolanco.mklt | M27: AMWT-CCI6FFYO7W | N27: Wear & Tear | O27: COMPLETE | P27: https://dashboard.paveapi.com/park/AMWT-CCI6FFYO7W/?l=en | Q27: 46143.495 | R27: 46143.497 | S27: 161 | T27: 46143.501 | U27: 1262 | V27: 2 | W27: 3360 | X27: 2 | Y27: 0 | Z27: 2 | AA27: 0 | AB27: 0 | AC27: 0 | AD27: 0 | AE27: 0 | AF27: USD | AG27: FALSE | AH27: FALSE | AI27: FALSE | AJ27: FALSE | AK27: FALSE | AL27: FALSE | AM27: View 4: Remove false positive damage. / Correct one. | AN27: 46143 | AO27: AMWT-CCI6FFYO7W | AT27: TRUE | AU27: FALSE | AV27: FALSE
B28: https://agent-admin.paveapi.com/inspectionView/AMWT-MIS6K6ORQ0?activeTab=past-sessions | C28: 7FCEHDB70NN005199 | D28: US | E28: 2022 | F28: Rivian | G28: Delivery | H28: CFDL | I28: DCL5 | J28: DSP Accounts | K28: CFDL | L28: JeffZ | M28: AMWT-MIS6K6ORQ0 | N28: Wear & Tear | O28: COMPLETE | P28: https://dashboard.paveapi.com/park/AMWT-MIS6K6ORQ0/?l=en | Q28: 46143.761 | R28: 46143.763 | S28: 139 | T28: 46143.766 | U28: 452 | V28: 2 | W28: 2215 | X28: 1 | Y28: 1 | Z28: 0 | AA28: 0 | AB28: 0 | AC28: 0 | AD28: 0 | AE28: 0 | AF28: USD | AG28: FALSE | AH28: FALSE | AI28: FALSE | AJ28: FALSE | AK28: FALSE | AL28: FALSE | AN28: 46143 | AO28: AMWT-MIS6K6ORQ0 | AS28: Hình tối | AT28: FALSE | AU28: TRUE | AV28: FALSE
B29: https://agent-admin.paveapi.com/inspectionView/AMWT-V5GYMWQ1SJ?activeTab=past-sessions | C29: 7FCEHDB70NN005199 | D29: US | E29: 2022 | F29: Rivian | G29: Delivery | H29: CFDL | I29: DCL5 | J29: DSP Accounts | K29: CFDL | L29: JeffZ | M29: AMWT-V5GYMWQ1SJ | N29: Wear & Tear | O29: COMPLETE | P29: https://dashboard.paveapi.com/park/AMWT-V5GYMWQ1SJ/?l=en | Q29: 46143.78 | R29: 46143.781 | S29: 130 | T29: 46143.784 | U29: 433 | V29: 5 | W29: 0 | X29: 0 | Y29: 0 | Z29: 0 | AA29: 0 | AB29: 0 | AC29: 0 | AD29: 0 | AE29: 0 | AF29: USD | AG29: FALSE | AH29: FALSE | AI29: FALSE | AJ29: FALSE | AK29: FALSE | AL29: FALSE | AM29: View 4,5: Remove false positive damages. / Correct one. | AN29: 46143 | AO29: AMWT-V5GYMWQ1SJ | AT29: TRUE | AU29: FALSE | AV29: FALSE
B30: https://agent-admin.paveapi.com/inspectionView/AMWT-9S6TPCCG8I?activeTab=past-sessions | C30: 7FCEHDB73NN000806 | D30: US | E30: 2022 | F30: Rivian | G30: Delivery | H30: SGLT | I30: DTU7 | J30: DSP Accounts | K30: SGLT | L30: SGLT.user | M30: AMWT-9S6TPCCG8I | N30: Fleet Improvement Fund | O30: COMPLETE | P30: https://dashboard.paveapi.com/park/AMWT-9S6TPCCG8I/?l=en | Q30: 46143.627 | R30: 46143.63 | S30: 182 | T30: 46143.632 | U30: 515 | V30: 2 | W30: 2100 | X30: 0 | Y30: 0 | Z30: 12 | AA30: 0 | AB30: 0 | AC30: 0 | AD30: 3 | AE30: 0 | AF30: USD | AG30: FALSE | AH30: FALSE | AI30: FALSE | AJ30: FALSE | AK30: FALSE | AL30: FALSE | AN30: 46143 | AO30: AMWT-9S6TPCCG8I | AP30: QA Wrong damage | AR30: uyen.tran | AS30: View 7: Damage OLD đã sửa chữa | AT30: FALSE | AU30: TRUE | AV30: TRUE
B31: https://agent-admin.paveapi.com/inspectionView/AMWT-RBSXDSQNMQ?activeTab=past-sessions | C31: 7FCEHDB73NN000806 | D31: US | E31: 2022 | F31: Rivian | G31: Delivery | H31: SGLT | I31: DTU7 | J31: DSP Accounts | K31: SGLT | L31: SGLT.user | M31: AMWT-RBSXDSQNMQ | N31: Fleet Improvement Fund | O31: COMPLETE | P31: https://dashboard.paveapi.com/park/AMWT-RBSXDSQNMQ/?l=en | Q31: 46143.636 | R31: 46143.637 | S31: 83 | T31: 46143.644 | U31: 801 | V31: 5 | W31: 0 | X31: 0 | Y31: 0 | Z31: 0 | AA31: 0 | AB31: 0 | AC31: 0 | AD31: 0 | AE31: 0 | AF31: USD | AG31: FALSE | AH31: FALSE | AI31: FALSE | AJ31: FALSE | AK31: FALSE | AL31: FALSE | AM31: View 7: Remove wrong damages. / Correct one. | AN31: 46143 | AO31: AMWT-RBSXDSQNMQ | AT31: TRUE | AU31: FALSE | AV31: FALSE
B32: https://agent-admin.paveapi.com/inspectionView/AMWT-AUCGARQFGH?activeTab=past-sessions | C32: 7FCEHEB21RN017183 | D32: US | E32: 2024 | F32: Rivian | G32: Delivery | H32: KJQY | I32: DRO2 | J32: DSP Accounts | K32: KJQY | L32: mitch.kjqy | M32: AMWT-AUCGARQFGH | N32: Fleet Improvement Fund | O32: COMPLETE | P32: https://dashboard.paveapi.com/park/AMWT-AUCGARQFGH/?l=en | Q32: 46143.436 | R32: 46143.437 | S32: 77 | T32: 46143.44 | U32: 404 | V32: 2 | W32: 4835 | X32: 2 | Y32: 3 | Z32: 13 | AA32: 0 | AB32: 2 | AC32: 0 | AD32: 3 | AE32: 0 | AF32: USD | AG32: FALSE | AH32: FALSE | AI32: FALSE | AJ32: FALSE | AK32: FALSE | AL32: FALSE | AN32: 46143 | AO32: AMWT-AUCGARQFGH | AT32: TRUE | AU32: FALSE | AV32: FALSE
B33: https://agent-admin.paveapi.com/inspectionView/AMWT-0C0GCQESDA?activeTab=past-sessions | C33: 7FCEHEB21RN017183 | D33: US | E33: 2024 | F33: Rivian | G33: DELIVERY | H33: KJQY | I33: DRO2 | J33: DSP Accounts | K33: KJQY | L33: mitch.kjqy | M33: AMWT-0C0GCQESDA | N33: Fleet Improvement Fund | O33: COMPLETE | P33: https://dashboard.paveapi.com/park/AMWT-0C0GCQESDA/?l=en | Q33: 46143.46 | R33: 46143.461 | S33: 77 | T33: 46143.465 | U33: 541 | V33: 3 | W33: 4662.5 | X33: 2 | Y33: 3 | Z33: 9 | AA33: 0 | AB33: 2 | AC33: 0 | AD33: 3 | AE33: 0 | AF33: USD | AG33: FALSE | AH33: FALSE | AI33: FALSE | AJ33: FALSE | AK33: FALSE | AL33: FALSE | AM33: View 7: Repaired. / Correct one. | AN33: 46143 | AO33: AMWT-0C0GCQESDA | AT33: TRUE | AU33: FALSE | AV33: FALSE
B34: https://agent-admin.paveapi.com/inspectionView/AMWT-KLPD5NL05J?activeTab=past-sessions | C34: 7FCEHEB22TN042939 | D34: US | E34: 2026 | F34: RIVIAN | G34: EDV | H34: ANKR | I34: DNJ7 | J34: DSP Accounts | K34: ANKR | M34: AMWT-KLPD5NL05J | N34: Wear & Tear | O34: COMPLETE | P34: https://dashboard.paveapi.com/park/AMWT-KLPD5NL05J/?l=en | Q34: 46143.531 | R34: 46143.533 | S34: 29 | T34: 46143.535 | U34: 463 | V34: 5 | W34: 0 | X34: 0 | Y34: 0 | Z34: 0 | AA34: 0 | AB34: 0 | AC34: 0 | AD34: 0 | AE34: 0 | AF34: USD | AG34: FALSE | AH34: FALSE | AI34: FALSE | AJ34: FALSE | AK34: FALSE | AL34: FALSE | AN34: 46143 | AO34: AMWT-KLPD5NL05J | AP34: QA Miss Damage | AR34: phu.nguyenhoang | AS34: View 8: BROKEN MAJOR - LIGHT TAIL LEFT | AT34: FALSE | AU34: TRUE | AV34: TRUE
B35: https://agent-admin.paveapi.com/inspectionView/AMWT-UXBCEOEFN1?activeTab=past-sessions | C35: 7FCEHEB22TN042939 | D35: US | E35: 2026 | F35: RIVIAN | G35: EDV | H35: ANKR | I35: DNJ7 | J35: DSP Accounts | K35: ANKR | M35: AMWT-UXBCEOEFN1 | N35: Fleet Improvement Fund | O35: COMPLETE | P35: https://dashboard.paveapi.com/park/AMWT-UXBCEOEFN1/?l=en | Q35: 46143.534 | R35: 46143.534 | S35: 46 | T35: 46143.541 | U35: 714 | V35: 5 | W35: 0 | X35: 0 | Y35: 0 | Z35: 0 | AA35: 0 | AB35: 0 | AC35: 0 | AD35: 0 | AE35: 0 | AF35: USD | AG35: FALSE | AH35: FALSE | AI35: FALSE | AJ35: FALSE | AK35: FALSE | AL35: FALSE | AN35: 46143 | AO35: AMWT-UXBCEOEFN1 | AT35: TRUE | AU35: FALSE | AV35: FALSE
B36: https://agent-admin.paveapi.com/inspectionView/AMWT-JDL0BNOD12?activeTab=past-sessions | C36: 5PVNJ7AV3N5T50187 | M36: AMWT-JDL0BNOD12 | AN36: 46143 | AO36: AMWT-JDL0BNOD12 | AP36: QA Miss Damage | AR36: tan.pham | AS36: View 5 : MISSING MAJOR - RIGHT SIDE FRONT CAB CORNER MOLDING | AT36: FALSE | AU36: TRUE | AV36: TRUE
A37: 0502-1hrs_NA | B37: https://agent-admin.paveapi.com/inspectionView/AMWT-1LAEWCDCAR?activeTab=past-sessions | C37: 1FTBR3X82MKA55958 | D37: US | E37: 2021 | F37: Ford | G37: Transit | H37: AUML | I37: HCH4 | J37: DSP Accounts | K37: AUML | L37: AUML.user | M37: AMWT-1LAEWCDCAR | N37: Wear & Tear | O37: COMPLETE | P37: https://dashboard.paveapi.com/park/AMWT-1LAEWCDCAR/?l=en | Q37: 46144.641 | R37: 46144.643 | S37: 155 | T37: 46144.646 | U37: 9216388 | V37: 3 | W37: 3387.5 | X37: 1 | Y37: 0 | Z37: 2 | AA37: 0 | AB37: 0 | AC37: 0 | AD37: 0 | AE37: 0 | AF37: USD | AG37: FALSE | AH37: FALSE | AI37: FALSE | AJ37: FALSE | AK37: FALSE | AL37: FALSE | AN37: 46144 | AO37: AMWT-1LAEWCDCAR | AT37: TRUE | AU37: FALSE | AV37: FALSE
B38: https://agent-admin.paveapi.com/inspectionView/AMWT-3E9EQPWOBS?activeTab=past-sessions | C38: 1FTBR3X82MKA55958 | D38: US | E38: 2021 | F38: Ford | G38: Transit | H38: AUML | I38: HCH4 | J38: DSP Accounts | K38: AUML | L38: AUML.user | M38: AMWT-3E9EQPWOBS | N38: Wear & Tear | O38: COMPLETE | P38: https://dashboard.paveapi.com/park/AMWT-3E9EQPWOBS/?l=en | Q38: 46144.644 | R38: 46144.645 | S38: 79 | T38: 46144.651 | U38: 14665 | V38: 3 | W38: 2437.5 | X38: 1 | Y38: 0 | Z38: 1 | AA38: 0 | AB38: 0 | AC38: 0 | AD38: 0 | AE38: 0 | AF38: USD | AG38: FALSE | AH38: FALSE | AI38: FALSE | AJ38: FALSE | AK38: FALSE | AL38: FALSE | AM38: View 7: Remove false positive damages. / Correct one. | AN38: 46144 | AO38: AMWT-3E9EQPWOBS | AT38: TRUE | AU38: FALSE | AV38: FALSE
B39: https://agent-admin.paveapi.com/inspectionView/AMWT-HZC42UEZLC?activeTab=past-sessions | C39: 3C6MRVJG7ME535539 | D39: US | E39: 2021 | F39: Ram | G39: ProMaster | H39: MNNA | I39: DCM5 | J39: DSP Accounts | K39: MNNA | L39: MESDispatch | M39: AMWT-HZC42UEZLC | N39: Wear & Tear | O39: COMPLETE | P39: https://dashboard.paveapi.com/park/AMWT-HZC42UEZLC/?l=en | Q39: 46144.726 | R39: 46144.729 | S39: 234 | T39: 46144.735 | U39: 905 | V39: 2 | W39: 4997.5 | X39: 1 | Y39: 2 | Z39: 4 | AA39: 2 | AB39: 0 | AC39: 0 | AD39: 0 | AE39: 0 | AF39: USD | AG39: FALSE | AH39: FALSE | AI39: FALSE | AJ39: FALSE | AK39: FALSE | AL39: FALSE | AN39: 46144 | AO39: AMWT-HZC42UEZLC | AP39: Agent + QA Wrong damage | AQ39: anh.le | AR39: huy.tran | AS39: View 7: (2, 3, 4) Damage OLD đã sửa chữa View 8: Hình tối -> skip | AT39: FALSE | AU39: TRUE | AV39: FALSE
B40: https://agent-admin.paveapi.com/inspectionView/AMWT-CLLIKUKPNM?activeTab=past-sessions | C40: 3C6MRVJG7ME535539 | D40: US | E40: 2021 | F40: Ram | G40: ProMaster | H40: MNNA | I40: DCM5 | J40: DSP Accounts | K40: MNNA | L40: MESDispatch | M40: AMWT-CLLIKUKPNM | N40: Wear & Tear | O40: COMPLETE | P40: https://dashboard.paveapi.com/park/AMWT-CLLIKUKPNM/?l=en | Q40: 46144.742 | R40: 46144.745 | S40: 209 | T40: 46144.749 | U40: 668 | V40: 4 | W40: 1137.5 | X40: 1 | Y40: 1 | Z40: 1 | AA40: 0 | AB40: 0 | AC40: 0 | AD40: 0 | AE40: 0 | AF40: USD | AG40: FALSE | AH40: FALSE | AI40: FALSE | AJ40: FALSE | AK40: FALSE | AL40: FALSE | AM40: View 5, 7, 8: Remove false positive damages. / Correct one. | AN40: 46144 | AO40: AMWT-CLLIKUKPNM | AP40: QA Wrong damage | AR40: huyhien.nguyen | AS40: View 5: (2) Xóa sai damage | AT40: FALSE | AU40: TRUE | AV40: FALSE
...

Sheet CONFIG
B1: Name | C1: User account | D1: Role
B2: Cao Đức Hiếu | C2: hieu.cao | D2: QA
B3: Huỳnh Thị Mỹ Kim | C3: kim.huynh | D3: QA | F3: ALL Miss Damage
B4: Nguyễn Lê Như Ý | C4: y.nguyen | D4: QA | F4: ALL Wrong Damage
B5: Hồ Thị Hải Yến | C5: yen.ho | D5: QA | F5: CC/AD Miss Damage
B6: Phạm Hà Duy Tân | C6: tan.pham | D6: QA | F6: CC/AD Wrong damage
B7: Lê Khả Nhi | C7: nhi.le | D7: QA | F7: Checker Miss Damage
B8: Mai Hà Bảo Trâm | C8: tram.mai | D8: QA | F8: Checker Wrong damage
B9: Hồ Tấn Phúc | C9: phuc.ho | D9: QA | F9: Checker + CC/AD Miss Damage
B10: Nguyễn Hoàng Duy Khang | C10: khang.nguyen | D10: QA | F10: Checker + CC/AD Wrong damage
B11: Bùi Nhật Anh | C11: anh.bui | D11: QA | F11: Inspector + CC/AD Miss Damage
B12: Thái Thị Thanh Linh | C12: linh.thai | D12: QA | F12: Inspector + CC/AD Wrong damage
B13: Nguyễn Phạm Thanh Bình | C13: binh.nguyen | D13: QA | F13: Inspector + Checker Miss Damage
B14: Nguyễn Thị Hòa | C14: hoa.nguyenthi | D14: QA | F14: Inspector + Checker Wrong damage
... B18: Huỳnh Tuyết Ngân | C18: ngan.huynhtuyet | D18: QA | F18: Other
B19: Nguyễn Mai Khánh Tâm | C19: tam.nguyenmaikhanh | D19: QA
B20: Lê Thị Quỳnh Như | C20: nhu.le | D20: QA
B21: Nguyễn Hữu Thiện | C21: thien.nguyen | D21: QA
B22: Nguyễn Thị Ánh Mỹ | C22: my.nguyen | D22: QA
B23: Nguyễn Văn Trưởng | C23: truong.nguyen | D23: QA
B24: Bùi Trọng Sơn | C24: son.bui | D24: QA
B25: Nguyễn Anh Vũ | C25: vu.nguyen | D25: QA
B26: Phan Xuân Thịnh | C26: thinh.phanxuan | D26: QA
B27: Võ Anh Kiệt | C27: kiet.voanh | D27: QA
B28: Ân Hồng Kim Ý | C28: y.anhongkim | D28: QA
B29: Lương Thị Ngân | C29: ngan.luongthi | D29: QA
B30: Lư Quang Trực | C30: truc.luquang | D30: QA
... B116: Trịnh Mỹ Nhân | C116: nhan.trinh | D116: TT

Sheet PERF_TEMPLATE
E1: DAMAGE FAILED | T1: PERSON RESPONSIBLE | Z1: ACCURACY
A2: Date | C2: Sessions | D2: {={"LINK SESSION"; IF(C3:C1210 = "", "", "https://agent-admin.paveapi.com/inspectionView/" & C3:C1210 & "?activeTab=past-sessions")}} -> LINK SESSION | E2: Left Side | H2: Front Side | K2: Right Side | N2: Back Side | Q2: Other Side | T2: Inspect | U2: Check | V2: Cross-Check/Admin | W2: RE-CHECK & NOTE | X2: Reason | Y2: Total Dmg Missing (Session) | Z2: Inspect | AB2: Check | AD2: Cross-Check/Admin | AF2: Total Damage | AH2: AUDITOR
E3: Inspect | F3: Check | G3: Cross-Check/Admin | H3: Inspect | I3: Check | J3: Cross-Check/Admin | K3: Inspect | L3: Check | M3: Cross-Check/Admin | N3: Inspect | O3: Check | P3: Cross-Check/Admin | Q3: Inspect | R3: Check | S3: Cross-Check/Admin | Z3: =IFERROR(__xludf.DUMMYFUNCTION("{""Mistakes"";ARRAYFORMULA(IF((T4:T1210 <> """") * (T4:T1210 <> ""developer"") * (X4:X1210 <> """"), IF(REGEXMATCH(X4:X1210, ""Inspector|ALL|Other""), N(E4:E1210) + N(H4:H1210) + N(K4:K1210) + N(N4:N1210) + N(Q4:Q1210), 0), """"))}"),"Mistakes") -> Mistakes | AA3: =IFERROR(__xludf.DUMMYFUNCTION("{""%"";ARRAYFORMULA(IF((T4:T1210 = """") + (X4:X1210 = """"), """", IF(T4:T1210 = ""developer"", """", IFERROR(IF(REGEXMATCH($X$4:$X1210, ""(ALL|Inspector).*Miss Damage""), 1 - Z4:Z1210 / ((($AF$4:$AF1210 + $AG$4:$AG1210 + ABS($AF$4:$AF1210 - $AG$4:$AG121"&"0)) / 2) + $Y$4:$Y1210), 1 - Z4:Z1210 / (($AF$4:$AF1210 + $AG$4:$AG1210 + ABS($AF$4:$AF1210 - $AG$4:$AG1210)) / 2)), 1))))}"),"%") -> % | AB3: =IFERROR(__xludf.DUMMYFUNCTION("{""Mistakes""; ARRAYFORMULA(IF((U4:U1210 = """") + ($X$4:$X1210 = """"), """", IF(REGEXMATCH($X$4:$X1210, ""Checker|ALL|Other""), N(F4:F1210) + N(I4:I1210) + N(L4:L1210) + N(O4:O1210) + N(R4:R1210), 0)))}"),"Mistakes") -> Mistakes | AC3: =IFERROR(__xludf.DUMMYFUNCTION("{""%""; ARRAYFORMULA(IF((U4:U1210 = """") + ($X$4:$X1210 = """"), """", IFERROR(IF(REGEXMATCH($X$4:$X1210, ""(ALL|Checker).*Miss Damage""), 1 - AB4:AB1210 / ((($AF$4:$AF1210 + $AG$4:$AG1210 + ABS($AF$4:$AF1210 - $AG$4:$AG1210)) / 2) + $Y$4:$Y1210), 1 - AB"&"4:AB1210 / ((($AF$4:$AF1210 + $AG$4:$AG1210 + ABS($AF$4:$AF1210 - $AG$4:$AG1210)) / 2))), 1)))}"),"%") -> % | AD3: =IFERROR(__xludf.DUMMYFUNCTION("{""Mistakes""; ARRAYFORMULA(IF((V4:V1210 = """") + (X4:X1210 = """"), """", IF(REGEXMATCH(X4:X1210, ""CC/AD|ALL|Other""), N(G4:G1210) + N(J4:J1210) + N(M4:M1210) + N(P4:P1210) + N(S4:S1210), 0)))}"),"Mistakes") -> Mistakes | AE3: =IFERROR(__xludf.DUMMYFUNCTION("{""%"";ARRAYFORMULA(IF((V4:V1210 = """") + ($X$4:$X1210 = """"), """", IFERROR(IF(REGEXMATCH($X$4:$X1210, ""ALL Miss Damage|.*CC/AD Miss Damage""), 1 - AD4:AD1210 / ((($AF$4:$AF1210 + $AG$4:$AG1210 + ABS($AF$4:$AF1210 - $AG$4:$AG1210)) / 2) + $Y$4:$Y1210)"&", 1 - AD4:AD1210 / (($AF$4:$AF1210 + $AG$4:$AG1210 + ABS($AF$4:$AF1210 - $AG$4:$AG1210)) / 2)), 1)))}"),"%") -> % | AF3: BEFORE | AG3: FINAL
A4: 0501-1hrs_NA | B4: 46143 | C4: AMWT-VBAPZIS7EW | D4: https://agent-admin.paveapi.com/inspectionView/AMWT-VBAPZIS7EW?activeTab=past-sessions | F4: 1 | L4: 1 | T4: developer | U4: thien.ht | W4: View 4: (3) Damage OLD xác định sai ( trầy nông) View 7: Missing Major Dent ở Front Door (ví dụ) | X4: Checker Wrong damage, Checker Miss Damage | Y4: 1 | Z4: =IFERROR(__xludf.DUMMYFUNCTION("""COMPUTED_VALUE"""),"") | AA4: =IFERROR(__xludf.DUMMYFUNCTION("""COMPUTED_VALUE"""),"") | AB4: =IFERROR(__xludf.DUMMYFUNCTION("""COMPUTED_VALUE"""),2.0) -> 2 | AC4: =IFERROR(__xludf.DUMMYFUNCTION("""COMPUTED_VALUE"""),0.9130434782608696) -> 0.91304348 | AD4: =IFERROR(__xludf.DUMMYFUNCTION("""COMPUTED_VALUE"""),"") | AE4: =IFERROR(__xludf.DUMMYFUNCTION("""COMPUTED_VALUE"""),"") | AF4: 22 | AG4: 4
B5: 46143 | C5: AMWT-4OBMFH3IF8 | D5: https://agent-admin.paveapi.com/inspectionView/AMWT-4OBMFH3IF8?activeTab=past-sessions | T5: developer | U5: thinh.phanxuan | V5: trinh.ho | Z5: =IFERROR(__xludf.DUMMYFUNCTION("""COMPUTED_VALUE"""),"") | AA5: =IFERROR(__xludf.DUMMYFUNCTION("""COMPUTED_VALUE"""),"") | AB5: =IFERROR(__xludf.DUMMYFUNCTION("""COMPUTED_VALUE"""),"") | AC5: =IFERROR(__xludf.DUMMYFUNCTION("""COMPUTED_VALUE"""),"") | AD5: =IFERROR(__xludf.DUMMYFUNCTION("""COMPUTED_VALUE"""),"") | AE5: =IFERROR(__xludf.DUMMYFUNCTION("""COMPUTED_VALUE"""),"") | AF5: 4 | AG5: 3
A6: 0507-1hrs_NA | B6: 46149 | C6: AMWT-LMLUSZZIS2 | D6: https://agent-admin.paveapi.com/inspectionView/AMWT-LMLUSZZIS2?activeTab=past-sessions | P6: 1 | T6: developer | V6: hoang.nguyentuyen | W6: View 8: (2) Damage NEW xác định sai | X6: CC/AD Wrong damage | Z6: =IFERROR(__xludf.DUMMYFUNCTION("""COMPUTED_VALUE"""),"") | AA6: =IFERROR(__xludf.DUMMYFUNCTION("""COMPUTED_VALUE"""),"") | AB6: =IFERROR(__xludf.DUMMYFUNCTION("""COMPUTED_VALUE"""),"") | AC6: =IFERROR(__xludf.DUMMYFUNCTION("""COMPUTED_VALUE"""),"") | AD6: =IFERROR(__xludf.DUMMYFUNCTION("""COMPUTED_VALUE"""),1.0) -> 1 | AE6: =IFERROR(__xludf.DUMMYFUNCTION("""COMPUTED_VALUE"""),0.9285714285714286) -> 0.92857143 | AF6: 14 | AG6: 6
Z7: =IFERROR(__xludf.DUMMYFUNCTION("""COMPUTED_VALUE"""),"") | AA7: =IFERROR(__xludf.DUMMYFUNCTION("""COMPUTED_VALUE"""),"") | AB7: =IFERROR(__xludf.DUMMYFUNCTION("""COMPUTED_VALUE"""),"") | AC7: =IFERROR(__xludf.DUMMYFUNCTION("""COMPUTED_VALUE"""),"") | AD7: =IFERROR(__xludf.DUMMYFUNCTION("""COMPUTED_VALUE"""),"") | AE7: =IFERROR(__xludf.DUMMYFUNCTION("""COMPUTED_VALUE"""),"")
Z8: =IFERROR(__xludf.DUMMYFUNCTION("""COMPUTED_VALUE"""),"") | AA8: =IFERROR(__xludf.DUMMYFUNCTION("""COMPUTED_VALUE"""),"") | AB8: =IFERROR(__xludf.DUMMYFUNCTION("""COMPUTED_VALUE"""),"") | AC8: =IFERROR(__xludf.DUMMYFUNCTION("""COMPUTED_VALUE"""),"") | AD8: =IFERROR(__xludf.DUMMYFUNCTION("""COMPUTED_VALUE"""),"") | AE8: =IFERROR(__xludf.DUMMYFUNCTION("""COMPUTED_VALUE"""),"")
Z9: =IFERROR(__xludf.DUMMYFUNCTION("""COMPUTED_VALUE"""),"") | AA9: =IFERROR(__xludf.DUMMYFUNCTION("""COMPUTED_VALUE"""),"") | AB9: =IFERROR(__xludf.DUMMYFUNCTION("""COMPUTED_VALUE"""),"") | AC9: =IFERROR(__xludf.DUMMYFUNCTION("""COMPUTED_VALUE"""),"") | AD9: =IFERROR(__xludf.DUMMYFUNCTION("""COMPUTED_VALUE"""),"") | AE9: =IFERROR(__xludf.DUMMYFUNCTION("""COMPUTED_VALUE"""),"")
Z10: =IFERROR(__xludf.DUMMYFUNCTION("""COMPUTED_VALUE"""),"") | AA10: =IFERROR(__xludf.DUMMYFUNCTION("""COMPUTED_VALUE"""),"") | AB10: =IFERROR(__xludf.DUMMYFUNCTION("""COMPUTED_VALUE"""),"") | AC10: =IFERROR(__xludf.DUMMYFUNCTION("""COMPUTED_VALUE"""),"") | AD10: =IFERROR(__xludf.DUMMYFUNCTION("""COMPUTED_VALUE"""),"") | AE10: =IFERROR(__xludf.DUMMYFUNCTION("""COMPUTED_VALUE"""),"")
Z11: =IFERROR(__xludf.DUMMYFUNCTION("""COMPUTED_VALUE"""),"") | AA11: =IFERROR(__xludf.DUMMYFUNCTION("""COMPUTED_VALUE"""),"") | AB11: =IFERROR(__xludf.DUMMYFUNCTION("""COMPUTED_VALUE"""),"") | AC11: =IFERROR(__xludf.DUMMYFUNCTION("""COMPUTED_VALUE"""),"") | AD11: =IFERROR(__xludf.DUMMYFUNCTION("""COMPUTED_VALUE"""),"") | AE11: =IFERROR(__xludf.DUMMYFUNCTION("""COMPUTED_VALUE"""),"")
Z12: =IFERROR(__xludf.DUMMYFUNCTION("""COMPUTED_VALUE"""),"") | AA12: =IFERROR(__xludf.DUMMYFUNCTION("""COMPUTED_VALUE"""),"") | AB12: =IFERROR(__xludf.DUMMYFUNCTION("""COMPUTED_VALUE"""),"") | AC12: =IFERROR(__xludf.DUMMYFUNCTION("""COMPUTED_VALUE"""),"") | AD12: =IFERROR(__xludf.DUMMYFUNCTION("""COMPUTED_VALUE"""),"") | AE12: =IFERROR(__xludf.DUMMYFUNCTION("""COMPUTED_VALUE"""),"")
Z13: =IFERROR(__xludf.DUMMYFUNCTION("""COMPUTED_VALUE"""),"") | AA13: =IFERROR(__xludf.DUMMYFUNCTION("""COMPUTED_VALUE"""),"") | AB13: =IFERROR(__xludf.DUMMYFUNCTION("""COMPUTED_VALUE"""),"") | AC13: =IFERROR(__xludf.DUMMYFUNCTION("""COMPUTED_VALUE"""),"") | AD13: =IFERROR(__xludf.DUMMYFUNCTION("""COMPUTED_VALUE"""),"") | AE13: =IFERROR(__xludf.DUMMYFUNCTION("""COMPUTED_VALUE"""),"")
Z14: =IFERROR(__xludf.DUMMYFUNCTION("""COMPUTED_VALUE"""),"") | AA14: =IFERROR(__xludf.DUMMYFUNCTION("""COMPUTED_VALUE"""),"") | AB14: =IFERROR(__xludf.DUMMYFUNCTION("""COMPUTED_VALUE"""),"") | AC14: =IFERROR(__xludf.DUMMYFUNCTION("""COMPUTED_VALUE"""),"") | AD14: =IFERROR(__xludf.DUMMYFUNCTION("""COMPUTED_VALUE"""),"") | AE14: =IFERROR(__xludf.DUMMYFUNCTION("""COMPUTED_VALUE"""),"")
Z15: =IFERROR(__xludf.DUMMYFUNCTION("""COMPUTED_VALUE"""),"") | AA15: =IFERROR(__xludf.DUMMYFUNCTION("""COMPUTED_VALUE"""),"") | AB15: =IFERROR(__xludf.DUMMYFUNCTION("""COMPUTED_VALUE"""),"") | AC15: =IFERROR(__xludf.DUMMYFUNCTION("""COMPUTED_VALUE"""),"") | AD15: =IFERROR(__xludf.DUMMYFUNCTION("""COMPUTED_VALUE"""),"") | AE15: =IFERROR(__xludf.DUMMYFUNCTION("""COMPUTED_VALUE"""),"")
Z16: =IFERROR(__xludf.DUMMYFUNCTION("""COMPUTED_VALUE"""),"") | AA16: =IFERROR(__xludf.DUMMYFUNCTION("""COMPUTED_VALUE"""),"") | AB16: =IFERROR(__xludf.DUMMYFUNCTION("""COMPUTED_VALUE"""),"") | AC16: =IFERROR(__xludf.DUMMYFUNCTION("""COMPUTED_VALUE"""),"") | AD16: =IFERROR(__xludf.DUMMYFUNCTION("""COMPUTED_VALUE"""),"") | AE16: =IFERROR(__xludf.DUMMYFUNCTION("""COMPUTED_VALUE"""),"")
Z17: =IFERROR(__xludf.DUMMYFUNCTION("""COMPUTED_VALUE"""),"") | AA17: =IFERROR(__xludf.DUMMYFUNCTION("""COMPUTED_VALUE"""),"") | AB17: =IFERROR(__xludf.DUMMYFUNCTION("""COMPUTED_VALUE"""),"") | AC17: =IFERROR(__xludf.DUMMYFUNCTION("""COMPUTED_VALUE"""),"") | AD17: =IFERROR(__xludf.DUMMYFUNCTION("""COMPUTED_VALUE"""),"") | AE17: =IFERROR(__xludf.DUMMYFUNCTION("""COMPUTED_VALUE"""),"")
Z18: =IFERROR(__xludf.DUMMYFUNCTION("""COMPUTED_VALUE"""),"") | AA18: =IFERROR(__xludf.DUMMYFUNCTION("""COMPUTED_VALUE"""),"") | AB18: =IFERROR(__xludf.DUMMYFUNCTION("""COMPUTED_VALUE"""),"") | AC18: =IFERROR(__xludf.DUMMYFUNCTION("""COMPUTED_VALUE"""),"") | AD18: =IFERROR(__xludf.DUMMYFUNCTION("""COMPUTED_VALUE"""),"") | AE18: =IFERROR(__xludf.DUMMYFUNCTION("""COMPUTED_VALUE"""),"")
... Z1210: =IFERROR(__xludf.DUMMYFUNCTION("""COMPUTED_VALUE"""),"") | AA1210: =IFERROR(__xludf.DUMMYFUNCTION("""COMPUTED_VALUE"""),"") | AB1210: =IFERROR(__xludf.DUMMYFUNCTION("""COMPUTED_VALUE"""),"") | AC1210: =IFERROR(__xludf.DUMMYFUNCTION("""COMPUTED_VALUE"""),"") | AD1210: =IFERROR(__xludf.DUMMYFUNCTION("""COMPUTED_VALUE"""),"") | AE1210: =IFERROR(__xludf.DUMMYFUNCTION("""COMPUTED_VALUE"""),"")

Sheet PERF_W20
E1: DAMAGE FAILED | T1: PERSON RESPONSIBLE | X1: =COUNTIF(X4:X650,"<>") -> 468 | Y1: ACCURACY
B2: DATE | C2: Sessions | D2: {={"LINK SESSION"; IF(C3:C650 = "", "", "https://agent-admin.paveapi.com/inspectionView/" & C3:C650 & "?activeTab=past-sessions")}} -> LINK SESSION | E2: Left Side | H2: Front Side | K2: Right Side | N2: Back Side | Q2: Other Side | T2: Inspect | U2: Check | V2: Cross-Check/Admin | W2: RE-CHECK & NOTE | X2: Reason | Y2: Inspect | AA2: Check | AC2: Cross-Check/Admin | AE2: Total Damage | AG2: AUDITOR
E3: Inspect | F3: Check | G3: Cross-Check/Admin | H3: Inspect | I3: Check | J3: Cross-Check/Admin | K3: Inspect | L3: Check | M3: Cross-Check/Admin | N3: Inspect | O3: Check | P3: Cross-Check/Admin | Q3: Inspect | R3: Check | S3: Cross-Check/Admin | Y3: {={"Mistakes";IF((T4:T650 <> "") * (T4:T650 <> "developer") * (X4:X650 <> ""), IF(ISNUMBER(MATCH(X4:X650, {"ALL Miss Damage"; "ALL Wrong Damage"; "Inspector + CC/AD Miss Damage"; "Inspector + CC/AD Wrong damage"; "Inspector + Checker Miss Damage"; "Inspector + Checker Wrong damage"; "Inspector Miss Damage"; "Inspector Wrong damage"; "Other"}, 0)), N(E4:E650) + N(H4:H650) + N(K4:K650) + N(N4:N650) + N(Q4:Q650), 0), "")}} -> Mistakes | Z3: =IFERROR(__xludf.DUMMYFUNCTION("{""%"";ARRAYFORMULA(IF((T4:T650 = """") + (X4:X650 = """"), """", IF(T4:T650 = ""developer"", """", IFERROR(IF(REGEXMATCH(LOWER($X$4:$X650), ""miss damage""), 1 - Y4:Y650 / ((($AE$4:$AE650 + $AF$4:$AF650 + ABS($AE$4:$AE650 - $AF$4:$AF650)) / 2) + Y4:Y650)"&", 1 - Y4:Y650 / (($AE$4:$AE650 + $AF$4:$AF650 + ABS($AE$4:$AE650 - $AF$4:$AF650)) / 2)), 1))))}"),"%") -> % | AA3: {={"Mistakes"; IF((U4:U650 = "") + (X4:X650 = ""), "", IF(ISNUMBER(MATCH(X4:X650, {"ALL Miss Damage"; "ALL Wrong Damage"; "Checker Miss Damage"; "Checker Wrong damage"; "Checker + CC/AD Miss Damage"; "Checker + CC/AD Wrong damage"; "Inspector + Checker Miss Damage"; "Inspector + Checker Wrong damage"; "Other"}, 0)), N(F4:F650) + N(I4:I650) + N(L4:L650) + N(O4:O650) + N(R4:R650), 0))}} -> Mistakes | AB3: =IFERROR(__xludf.DUMMYFUNCTION("{""%"";ARRAYFORMULA(IF((U4:U650 = """") + (X4:X650 = """"), """", IFERROR(IF(REGEXMATCH(LOWER($X$4:$X650), ""miss damage""), 1 - AA4:AA650 / ((($AE$4:$AE650 + $AF$4:$AF650 + ABS($AE$4:$AE650 - $AF$4:$AF650)) / 2) + AA4:AA650), 1 - AA4:AA650 / (($AE$4:$AE6"&"50 + $AF$4:$AF650 + ABS($AE$4:$AE650 - $AF$4:$AF650)) / 2)), 1)))}"),"%") -> % | AC3: {={"Mistakes"; IF((V4:V650 = "") + (X4:X650 = ""), "", IF(ISNUMBER(MATCH(X4:X650, {"ALL Miss Damage"; "ALL Wrong Damage"; "CC/AD Miss Damage"; "CC/AD Wrong damage"; "Checker + CC/AD Miss Damage"; "Checker + CC/AD Wrong damage" ; "Inspector + CC/AD Miss Damage"; "Inspector + CC/AD Wrong damage"; "Other"}, 0)), N(G4:G650) + N(J4:J650) + N(M4:M650) + N(P4:P650) + N(S4:S650), 0))}} -> Mistakes | AD3: =IFERROR(__xludf.DUMMYFUNCTION("{""%"";ARRAYFORMULA(IF((V4:V650 = """") + (X4:X650 = """"), """", IFERROR(IF(REGEXMATCH(LOWER($X$4:$X650), ""miss damage""), 1 - AC4:AC650 / ((($AE$4:$AE650 + $AF$4:$AF650 + ABS($AE$4:$AE650 - $AF$4:$AF650)) / 2) + AC4:AC650), 1 - AC4:AC650 / (($AE$4:$AE6"&"50 + $AF$4:$AF650 + ABS($AE$4:$AE650 - $AF$4:$AF650)) / 2)), 1)))}"),"%") -> % | AE3: BEFORE | AF3: FINAL
B4: 46153 | C4: AMWT-IZZK98BHX8 | D4: https://agent-admin.paveapi.com/inspectionView/AMWT-IZZK98BHX8?activeTab=past-sessions | F4: 1 | L4: 1 | O4: 3 | T4: developer | U4: an.nguyen | W4: View 4: (14) Damage OLD đã sửa chữa View 8: (2, 3, 6) Damage OLD đã sửa chữa View 7: (20) Damage NEW xác định sai | X4: Checker Wrong damage | Z4: =IFERROR(__xludf.DUMMYFUNCTION("""COMPUTED_VALUE"""),"") | AA4: 5 | AB4: =IFERROR(__xludf.DUMMYFUNCTION("""COMPUTED_VALUE"""),0.8913043478260869) -> 0.89130435 | AD4: =IFERROR(__xludf.DUMMYFUNCTION("""COMPUTED_VALUE"""),"") | AE4: 46 | AF4: 14
B5: 46153 | C5: AMWT-MKGKOJFNIY | D5: https://agent-admin.paveapi.com/inspectionView/AMWT-MKGKOJFNIY?activeTab=past-sessions | T5: developer | U5: kim.huynh | V5: danh.huynh | X5: None | Z5: =IFERROR(__xludf.DUMMYFUNCTION("""COMPUTED_VALUE"""),"") | AA5: 0 | AB5: =IFERROR(__xludf.DUMMYFUNCTION("""COMPUTED_VALUE"""),1.0) -> 1 | AC5: 0 | AD5: =IFERROR(__xludf.DUMMYFUNCTION("""COMPUTED_VALUE"""),1.0) -> 1 | AE5: 14 | AF5: 10
B6: 46153 | C6: AMWT-UW1ZEONGE9 | D6: https://agent-admin.paveapi.com/inspectionView/AMWT-UW1ZEONGE9?activeTab=past-sessions | T6: developer | U6: son.bui | V6: danh.huynh | X6: None | Z6: =IFERROR(__xludf.DUMMYFUNCTION("""COMPUTED_VALUE"""),"") | AA6: 0 | AB6: =IFERROR(__xludf.DUMMYFUNCTION("""COMPUTED_VALUE"""),1.0) -> 1 | AC6: 0 | AD6: =IFERROR(__xludf.DUMMYFUNCTION("""COMPUTED_VALUE"""),1.0) -> 1 | AE6: 11 | AF6: 9
B7: 46153 | C7: AMWT-C4RJDG2OSA | D7: https://agent-admin.paveapi.com/inspectionView/AMWT-C4RJDG2OSA?activeTab=past-sessions | T7: huy.tran | U7: thanhha.tran | X7: None | Y7: 0 | Z7: =IFERROR(__xludf.DUMMYFUNCTION("""COMPUTED_VALUE"""),1.0) -> 1 | AA7: 0 | AB7: =IFERROR(__xludf.DUMMYFUNCTION("""COMPUTED_VALUE"""),1.0) -> 1 | AD7: =IFERROR(__xludf.DUMMYFUNCTION("""COMPUTED_VALUE"""),"") | AE7: 3 | AF7: 2
B8: 46153 | C8: AMWT-HKX2NVABEU | D8: https://agent-admin.paveapi.com/inspectionView/AMWT-HKX2NVABEU?activeTab=past-sessions | T8: thuy.ngodiem | U8: thanhha.tran | V8: cuong.pham | W8: Xóa damage ID trước đánh nghi ngờ | X8: None | Y8: 0 | Z8: =IFERROR(__xludf.DUMMYFUNCTION("""COMPUTED_VALUE"""),1.0) -> 1 | AA8: 0 | AB8: =IFERROR(__xludf.DUMMYFUNCTION("""COMPUTED_VALUE"""),1.0) -> 1 | AC8: 0 | AD8: =IFERROR(__xludf.DUMMYFUNCTION("""COMPUTED_VALUE"""),1.0) -> 1 | AE8: 2 | AF8: 0
B9: 46153 | C9: AMWT-XRQNZPENHF | D9: https://agent-admin.paveapi.com/inspectionView/AMWT-XRQNZPENHF?activeTab=past-sessions | T9: duy.nk | U9: nhi.le | X9: None | Y9: 0 | Z9: =IFERROR(__xludf.DUMMYFUNCTION("""COMPUTED_VALUE"""),1.0) -> 1 | AA9: 0 | AB9: =IFERROR(__xludf.DUMMYFUNCTION("""COMPUTED_VALUE"""),1.0) -> 1 | AD9: =IFERROR(__xludf.DUMMYFUNCTION("""COMPUTED_VALUE"""),"") | AE9: 32 | AF9: 9
B10: 46153 | C10: AMWT-UORN9VRMOC | D10: https://agent-admin.paveapi.com/inspectionView/AMWT-UORN9VRMOC?activeTab=past-sessions | T10: tho.nh | U10: an.nguyen | V10: sang.tran | W10: Xóa damage ID trước đánh nghi ngờ | X10: None | Y10: 0 | Z10: =IFERROR(__xludf.DUMMYFUNCTION("""COMPUTED_VALUE"""),1.0) -> 1 | AA10: 0 | AB10: =IFERROR(__xludf.DUMMYFUNCTION("""COMPUTED_VALUE"""),1.0) -> 1 | AC10: 0 | AD10: =IFERROR(__xludf.DUMMYFUNCTION("""COMPUTED_VALUE"""),1.0) -> 1 | AE10: 10 | AF10: 6
B11: 46153 | C11: AMWT-D7CU8TCF5Z | D11: https://agent-admin.paveapi.com/inspectionView/AMWT-D7CU8TCF5Z?activeTab=past-sessions | O11: 1 | T11: developer | U11: que.nguyenthihong | W11: View 8: (4) Damage OLD đã sửa chữa | X11: Checker Wrong damage | Z11: =IFERROR(__xludf.DUMMYFUNCTION("""COMPUTED_VALUE"""),"") | AA11: 1 | AB11: =IFERROR(__xludf.DUMMYFUNCTION("""COMPUTED_VALUE"""),0.9166666666666666) -> 0.91666667 | AD11: =IFERROR(__xludf.DUMMYFUNCTION("""COMPUTED_VALUE"""),"") | AE11: 12 | AF11: 4
B12: 46153 | C12: AMWT-LQYYGFMDI0 | D12: https://agent-admin.paveapi.com/inspectionView/AMWT-LQYYGFMDI0?activeTab=past-sessions | T12: developer | U12: nhu.le | V12: huyhien.nguyen | W12: View 7: (1) Damage OLD kích thước nhỏ -> skip ok | X12: None | Z12: =IFERROR(__xludf.DUMMYFUNCTION("""COMPUTED_VALUE"""),"") | AA12: 0 | AB12: =IFERROR(__xludf.DUMMYFUNCTION("""COMPUTED_VALUE"""),1.0) -> 1 | AC12: 0 | AD12: =IFERROR(__xludf.DUMMYFUNCTION("""COMPUTED_VALUE"""),1.0) -> 1 | AE12: 5 | AF12: 2
B13: 46154 | C13: AMWT-06O0KM5HY9 | D13: https://agent-admin.paveapi.com/inspectionView/AMWT-06O0KM5HY9?activeTab=past-sessions | T13: developer | U13: huy.tran | X13: None | Z13: =IFERROR(__xludf.DUMMYFUNCTION("""COMPUTED_VALUE"""),"") | AA13: 0 | AB13: =IFERROR(__xludf.DUMMYFUNCTION("""COMPUTED_VALUE"""),1.0) -> 1 | AD13: =IFERROR(__xludf.DUMMYFUNCTION("""COMPUTED_VALUE"""),"") | AE13: 2 | AF13: 2
B14: 46154 | C14: AMWT-F3ZN6GY5IO | D14: https://agent-admin.paveapi.com/inspectionView/AMWT-F3ZN6GY5IO?activeTab=past-sessions | T14: developer | U14: ngan.huynhtuyet | V14: tong.nguyen | W14: Xóa damage ID trước đánh nghi ngờ | X14: None | Z14: =IFERROR(__xludf.DUMMYFUNCTION("""COMPUTED_VALUE"""),"") | AA14: 0 | AB14: =IFERROR(__xludf.DUMMYFUNCTION("""COMPUTED_VALUE"""),1.0) -> 1 | AC14: 0 | AD14: =IFERROR(__xludf.DUMMYFUNCTION("""COMPUTED_VALUE"""),1.0) -> 1 | AE14: 2 | AF14: 1
B15: 46154 | C15: AMWT-VBXLEAI2GP | D15: https://agent-admin.paveapi.com/inspectionView/AMWT-VBXLEAI2GP?activeTab=past-sessions | F15: 1 | L15: 1 | O15: 1 | T15: developer | U15: nam.nguyendinh | W15: View 4: (9) Damage OLD kích thước nhỏ View 7: (5) Damage OLD kích thước nhỏ View 8: (3) Damage OLD kích thước nhỏ | X15: Checker Wrong damage | Z15: =IFERROR(__xludf.DUMMYFUNCTION("""COMPUTED_VALUE"""),"") | AA15: 3 | AB15: =IFERROR(__xludf.DUMMYFUNCTION("""COMPUTED_VALUE"""),0.8571428571428572) -> 0.85714286 | AD15: =IFERROR(__xludf.DUMMYFUNCTION("""COMPUTED_VALUE"""),"") | AE15: 21 | AF15: 10
B16: 46154 | C16: AMRR-HFMYLBSUCM | D16: https://agent-admin.paveapi.com/inspectionView/AMRR-HFMYLBSUCM?activeTab=past-sessions | T16: developer | U16: thao.phan | V16: danh.huynh | X16: None | Z16: =IFERROR(__xludf.DUMMYFUNCTION("""COMPUTED_VALUE"""),"") | AA16: 0 | AB16: =IFERROR(__xludf.DUMMYFUNCTION("""COMPUTED_VALUE"""),1.0) -> 1 | AC16: 0 | AD16: =IFERROR(__xludf.DUMMYFUNCTION("""COMPUTED_VALUE"""),1.0) -> 1 | AE16: 10 | AF16: 7
B17: 46154 | C17: AMWT-EA2OIU0MPB | D17: https://agent-admin.paveapi.com/inspectionView/AMWT-EA2OIU0MPB?activeTab=past-sessions | I17: 1 | O17: 1 | T17: developer | U17: nhi.le | W17: View 5: (1) Damage OLD xác định sai View 8: (2) Damage OLD xác định sai | X17: Checker Wrong damage | Z17: =IFERROR(__xludf.DUMMYFUNCTION("""COMPUTED_VALUE"""),"") | AA17: 2 | AB17: =IFERROR(__xludf.DUMMYFUNCTION("""COMPUTED_VALUE"""),0.9130434782608696) -> 0.91304348 | AD17: =IFERROR(__xludf.DUMMYFUNCTION("""COMPUTED_VALUE"""),"") | AE17: 23 | AF17: 23
B18: 46154 | C18: AMWT-XGITTHQWMY | D18: https://agent-admin.paveapi.com/inspectionView/AMWT-XGITTHQWMY?activeTab=past-sessions | T18: developer | U18: tho.nh | V18: danh.huynh | X18: None | Z18: =IFERROR(__xludf.DUMMYFUNCTION("""COMPUTED_VALUE"""),"") | AA18: 0 | AB18: =IFERROR(__xludf.DUMMYFUNCTION("""COMPUTED_VALUE"""),1.0) -> 1 | AC18: 0 | AD18: =IFERROR(__xludf.DUMMYFUNCTION("""COMPUTED_VALUE"""),1.0) -> 1 | AE18: 24 | AF18: 21
B19: 46154 | C19: AMWT-BOHVMSMU0R | D19: https://agent-admin.paveapi.com/inspectionView/AMWT-BOHVMSMU0R?activeTab=past-sessions | T19: developer | U19: son.bui | X19: None | Z19: =IFERROR(__xludf.DUMMYFUNCTION("""COMPUTED_VALUE"""),"") | AA19: 0 | AB19: =IFERROR(__xludf.DUMMYFUNCTION("""COMPUTED_VALUE"""),1.0) -> 1 | AD19: =IFERROR(__xludf.DUMMYFUNCTION("""COMPUTED_VALUE"""),"") | AE19: 18 | AF19: 14
B20: 46154 | C20: AMWT-IWCNM0XMGN | D20: https://agent-admin.paveapi.com/inspectionView/AMWT-IWCNM0XMGN?activeTab=past-sessions | T20: developer | U20: luu.nguyendinh | V20: danh.huynh | W20: Xóa damage ID trước đánh nghi ngờ | X20: None | Z20: =IFERROR(__xludf.DUMMYFUNCTION("""COMPUTED_VALUE"""),"") | AA20: 0 | AB20: =IFERROR(__xludf.DUMMYFUNCTION("""COMPUTED_VALUE"""),1.0) -> 1 | AC20: 0 | AD20: =IFERROR(__xludf.DUMMYFUNCTION("""COMPUTED_VALUE"""),1.0) -> 1 | AE20: 14 | AF20: 12
B21: 46154 | C21: AMWT-3YIUPGJMKR | D21: https://agent-admin.paveapi.com/inspectionView/AMWT-3YIUPGJMKR?activeTab=past-sessions | H21: 1 | I21: 1 | K21: 1 | L21: 1 | T21: vi.votuan | U21: kien.nguyen | W21: View 5: (2) Damage NEW xác định sai View 7: (3) Damage NEW xác định sai | X21: Inspector + Checker Wrong damage | Y21: 2 | Z21: =IFERROR(__xludf.DUMMYFUNCTION("""COMPUTED_VALUE"""),0.6) -> 0.6 | AA21: 2 | AB21: =IFERROR(__xludf.DUMMYFUNCTION("""COMPUTED_VALUE"""),0.6) -> 0.6 | AD21: =IFERROR(__xludf.DUMMYFUNCTION("""COMPUTED_VALUE"""),"") | AE21: 5 | AF21: 4
B22: 46154 | C22: AMUO-YSKGX5S8QU | D22: https://agent-admin.paveapi.com/inspectionView/AMUO-YSKGX5S8QU?activeTab=past-sessions | T22: phong.phantrung | U22: duy.nk | V22: tong.nguyen | X22: None | Y22: 0 | Z22: =IFERROR(__xludf.DUMMYFUNCTION("""COMPUTED_VALUE"""),1.0) -> 1 | AA22: 0 | AB22: =IFERROR(__xludf.DUMMYFUNCTION("""COMPUTED_VALUE"""),1.0) -> 1 | AC22: 0 | AD22: =IFERROR(__xludf.DUMMYFUNCTION("""COMPUTED_VALUE"""),1.0) -> 1 | AE22: 4 | AF22: 1
B23: 46154 | C23: AMWT-JFRVOZENDZ | D23: https://agent-admin.paveapi.com/inspectionView/AMWT-JFRVOZENDZ?activeTab=past-sessions | T23: danh.phamcong | U23: quang.phamdoduy | X23: None | Y23: 0 | Z23: =IFERROR(__xludf.DUMMYFUNCTION("""COMPUTED_VALUE"""),1.0) -> 1 | AA23: 0 | AB23: =IFERROR(__xludf.DUMMYFUNCTION("""COMPUTED_VALUE"""),1.0) -> 1 | AD23: =IFERROR(__xludf.DUMMYFUNCTION("""COMPUTED_VALUE"""),"") | AE23: 18 | AF23: 17
B24: 46154 | C24: AMWT-ZLPMAONCMN | D24: https://agent-admin.paveapi.com/inspectionView/AMWT-ZLPMAONCMN?activeTab=past-sessions | T24: thuy.ngodiem | U24: tam.nguyenmaikhanh | V24: thong.nhat | W24: Xóa damage ID trước đánh nghi ngờ | X24: None | Y24: 0 | Z24: =IFERROR(__xludf.DUMMYFUNCTION("""COMPUTED_VALUE"""),1.0) -> 1 | AA24: 0 | AB24: =IFERROR(__xludf.DUMMYFUNCTION("""COMPUTED_VALUE"""),1.0) -> 1 | AC24: 0 | AD24: =IFERROR(__xludf.DUMMYFUNCTION("""COMPUTED_VALUE"""),1.0) -> 1 | AE24: 18 | AF24: 15
B25: 46154 | C25: AMWT-WF3JDKQCX1 | D25: https://agent-admin.paveapi.com/inspectionView/AMWT-WF3JDKQCX1?activeTab=past-sessions | T25: dinhtu.tran | U25: quang.phamdoduy | W25: Hình tối + sửa xấu -> sp | X25: None | Y25: 0 | Z25: =IFERROR(__xludf.DUMMYFUNCTION("""COMPUTED_VALUE"""),1.0) -> 1 | AA25: 0 | AB25: =IFERROR(__xludf.DUMMYFUNCTION("""COMPUTED_VALUE"""),1.0) -> 1 | AD25: =IFERROR(__xludf.DUMMYFUNCTION("""COMPUTED_VALUE"""),"") | AE25: 12 | AF25: 12
B26: 46154 | C26: AMWT-2JETA15LXZ | D26: https://agent-admin.paveapi.com/inspectionView/AMWT-2JETA15LXZ?activeTab=past-sessions | T26: developer | U26: quang.phamdoduy | V26: hien.nhu | X26: None | Z26: =IFERROR(__xludf.DUMMYFUNCTION("""COMPUTED_VALUE"""),"") | AA26: 0 | AB26: =IFERROR(__xludf.DUMMYFUNCTION("""COMPUTED_VALUE"""),1.0) -> 1 | AC26: 0 | AD26: =IFERROR(__xludf.DUMMYFUNCTION("""COMPUTED_VALUE"""),1.0) -> 1 | AE26: 12 | AF26: 10
B27: 46154 | C27: AMWT-URCX2MK1CT | D27: https://agent-admin.paveapi.com/inspectionView/AMWT-URCX2MK1CT?activeTab=past-sessions | I27: 1 | T27: developer | U27: anh.nguyen | W27: View 5: (3) Damage OLD xác định sai | X27: Checker Wrong damage | Z27: =IFERROR(__xludf.DUMMYFUNCTION("""COMPUTED_VALUE"""),"") | AA27: 1 | AB27: =IFERROR(__xludf.DUMMYFUNCTION("""COMPUTED_VALUE"""),0.75) -> 0.75 | AD27: =IFERROR(__xludf.DUMMYFUNCTION("""COMPUTED_VALUE"""),"") | AE27: 4 | AF27: 4
B28: 46154 | C28: AMWT-77NMRGHZOK | D28: https://agent-admin.paveapi.com/inspectionView/AMWT-77NMRGHZOK?activeTab=past-sessions | T28: developer | U28: vu.nguyen | V28: huyhien.nguyen | X28: None | Z28: =IFERROR(__xludf.DUMMYFUNCTION("""COMPUTED_VALUE"""),"") | AA28: 0 | AB28: =IFERROR(__xludf.DUMMYFUNCTION("""COMPUTED_VALUE"""),1.0) -> 1 | AC28: 0 | AD28: =IFERROR(__xludf.DUMMYFUNCTION("""COMPUTED_VALUE"""),1.0) -> 1 | AE28: 4 | AF28: 2
B29: 46154 | C29: AMWT-GIJQEVY73C | D29: https://agent-admin.paveapi.com/inspectionView/AMWT-GIJQEVY73C?activeTab=past-sessions | O29: 2 | T29: developer | U29: nam.nguyendinh | W29: View 8: (3) Damage OLD xác định sai View 8: BADGE - MISSING_MAJOR | X29: Checker Miss Damage | Z29: =IFERROR(__xludf.DUMMYFUNCTION("""COMPUTED_VALUE"""),"") | AA29: 2 | AB29: =IFERROR(__xludf.DUMMYFUNCTION("""COMPUTED_VALUE"""),0.7142857142857143) -> 0.71428571 | AD29: =IFERROR(__xludf.DUMMYFUNCTION("""COMPUTED_VALUE"""),"") | AE29: 5 | AF29: 3
B30: 46154 | C30: AMWT-ZMZWVMQIKE | D30: https://agent-admin.paveapi.com/inspectionView/AMWT-ZMZWVMQIKE?activeTab=past-sessions | T30: anh.le | U30: nam.nguyendinh | V30: huyhien.nguyen | X30: None | Y30: 0 | Z30: =IFERROR(__xludf.DUMMYFUNCTION("""COMPUTED_VALUE"""),1.0) -> 1 | AA30: 0 | AB30: =IFERROR(__xludf.DUMMYFUNCTION("""COMPUTED_VALUE"""),1.0) -> 1 | AC30: 0 | AD30: =IFERROR(__xludf.DUMMYFUNCTION("""COMPUTED_VALUE"""),1.0) -> 1 | AE30: 3 | AF30: 2
B31: 46154 | C31: AMWT-BWBEHP0X3F | D31: https://agent-admin.paveapi.com/inspectionView/AMWT-BWBEHP0X3F?activeTab=past-sessions | L31: 2 | T31: developer | U31: anh.nguyen | W31: View 7: (3, 4) Damage NEW xác định sai | X31: Checker Wrong damage | Z31: =IFERROR(__xludf.DUMMYFUNCTION("""COMPUTED_VALUE"""),"") | AA31: 2 | AB31: =IFERROR(__xludf.DUMMYFUNCTION("""COMPUTED_VALUE"""),0.8) -> 0.8 | AD31: =IFERROR(__xludf.DUMMYFUNCTION("""COMPUTED_VALUE"""),"") | AE31: 10 | AF31: 10
B32: 46154 | C32: AMWT-IMTSQGKNGM | D32: https://agent-admin.paveapi.com/inspectionView/AMWT-IMTSQGKNGM?activeTab=past-sessions | T32: developer | U32: uyen.tran | V32: nhat.ngo | X32: None | Z32: =IFERROR(__xludf.DUMMYFUNCTION("""COMPUTED_VALUE"""),"") | AA32: 0 | AB32: =IFERROR(__xludf.DUMMYFUNCTION("""COMPUTED_VALUE"""),1.0) -> 1 | AC32: 0 | AD32: =IFERROR(__xludf.DUMMYFUNCTION("""COMPUTED_VALUE"""),1.0) -> 1 | AE32: 12 | AF32: 8
B33: 46154 | C33: DIL1-N9RGCBWVV5 | D33: https://agent-admin.paveapi.com/inspectionView/DIL1-N9RGCBWVV5?activeTab=past-sessions | N33: 1 | O33: 1 | T33: tuong.nhambon | U33: duy.nguyenhuynhquoc | W33: View 8: (1) Damage OLD xác định sai | X33: Inspector + Checker Wrong damage | Y33: 1 | Z33: =IFERROR(__xludf.DUMMYFUNCTION("""COMPUTED_VALUE"""),0.8571428571428572) -> 0.85714286 | AA33: 1 | AB33: =IFERROR(__xludf.DUMMYFUNCTION("""COMPUTED_VALUE"""),0.8571428571428572) -> 0.85714286 | AD33: =IFERROR(__xludf.DUMMYFUNCTION("""COMPUTED_VALUE"""),"") | AE33: 7 | AF33: 7
B34: 46154 | C34: DIL1-UKO8ICTQ6K | D34: https://agent-admin.paveapi.com/inspectionView/DIL1-UKO8ICTQ6K?activeTab=past-sessions | T34: thuy.ngodiem | U34: anh.nguyen | V34: anh.dao | W34: View 8: Xóa damage ID trước đánh nghi ngờ | X34: None | Y34: 0 | Z34: =IFERROR(__xludf.DUMMYFUNCTION("""COMPUTED_VALUE"""),1.0) -> 1 | AA34: 0 | AB34: =IFERROR(__xludf.DUMMYFUNCTION("""COMPUTED_VALUE"""),1.0) -> 1 | AC34: 0 | AD34: =IFERROR(__xludf.DUMMYFUNCTION("""COMPUTED_VALUE"""),1.0) -> 1 | AE34: 7 | AF34: 6
B35: 46155 | C35: AMWT-AQQPAZUF0B | D35: https://agent-admin.paveapi.com/inspectionView/AMWT-AQQPAZUF0B?activeTab=past-sessions | T35: developer | U35: vi.votuan | X35: None | Z35: =IFERROR(__xludf.DUMMYFUNCTION("""COMPUTED_VALUE"""),"") | AA35: 0 | AB35: =IFERROR(__xludf.DUMMYFUNCTION("""COMPUTED_VALUE"""),1.0) -> 1 | AD35: =IFERROR(__xludf.DUMMYFUNCTION("""COMPUTED_VALUE"""),"") | AE35: 8 | AF35: 7
